2023-11-04 03:29:37 ERROR Internal Server Error: /api/articles/ C:\Users\ekad1\PycharmProjects\DjangoProjects\News Portal\venv\Lib\site-packages\django\utils\log.py (<class 'django.core.exceptions.ImproperlyConfigured'>, ImproperlyConfigured('Field name `type` is not valid for model `Post`.'), <traceback object at 0x0000020430605380>)
Traceback (most recent call last):
  File "C:\Users\ekad1\PycharmProjects\DjangoProjects\News Portal\venv\Lib\site-packages\django\core\handlers\exception.py", line 55, in inner
    response = get_response(request)
               ^^^^^^^^^^^^^^^^^^^^^
  File "C:\Users\ekad1\PycharmProjects\DjangoProjects\News Portal\venv\Lib\site-packages\django\core\handlers\base.py", line 197, in _get_response
    response = wrapped_callback(request, *callback_args, **callback_kwargs)
               ^^^^^^^^^^^^^^^^^^^^^^^^^^^^^^^^^^^^^^^^^^^^^^^^^^^^^^^^^^^^
  File "C:\Users\ekad1\PycharmProjects\DjangoProjects\News Portal\venv\Lib\site-packages\django\views\decorators\csrf.py", line 56, in wrapper_view
    return view_func(*args, **kwargs)
           ^^^^^^^^^^^^^^^^^^^^^^^^^^
  File "C:\Users\ekad1\PycharmProjects\DjangoProjects\News Portal\venv\Lib\site-packages\rest_framework\viewsets.py", line 125, in view
    return self.dispatch(request, *args, **kwargs)
           ^^^^^^^^^^^^^^^^^^^^^^^^^^^^^^^^^^^^^^^
  File "C:\Users\ekad1\PycharmProjects\DjangoProjects\News Portal\venv\Lib\site-packages\rest_framework\views.py", line 509, in dispatch
    response = self.handle_exception(exc)
               ^^^^^^^^^^^^^^^^^^^^^^^^^^
  File "C:\Users\ekad1\PycharmProjects\DjangoProjects\News Portal\venv\Lib\site-packages\rest_framework\views.py", line 469, in handle_exception
    self.raise_uncaught_exception(exc)
  File "C:\Users\ekad1\PycharmProjects\DjangoProjects\News Portal\venv\Lib\site-packages\rest_framework\views.py", line 480, in raise_uncaught_exception
    raise exc
  File "C:\Users\ekad1\PycharmProjects\DjangoProjects\News Portal\venv\Lib\site-packages\rest_framework\views.py", line 506, in dispatch
    response = handler(request, *args, **kwargs)
               ^^^^^^^^^^^^^^^^^^^^^^^^^^^^^^^^^
  File "C:\Users\ekad1\PycharmProjects\DjangoProjects\News Portal\venv\Lib\site-packages\rest_framework\mixins.py", line 46, in list
    return Response(serializer.data)
                    ^^^^^^^^^^^^^^^
  File "C:\Users\ekad1\PycharmProjects\DjangoProjects\News Portal\venv\Lib\site-packages\rest_framework\serializers.py", line 768, in data
    ret = super().data
          ^^^^^^^^^^^^
  File "C:\Users\ekad1\PycharmProjects\DjangoProjects\News Portal\venv\Lib\site-packages\rest_framework\serializers.py", line 253, in data
    self._data = self.to_representation(self.instance)
                 ^^^^^^^^^^^^^^^^^^^^^^^^^^^^^^^^^^^^^
  File "C:\Users\ekad1\PycharmProjects\DjangoProjects\News Portal\venv\Lib\site-packages\rest_framework\serializers.py", line 686, in to_representation
    return [
           ^
  File "C:\Users\ekad1\PycharmProjects\DjangoProjects\News Portal\venv\Lib\site-packages\rest_framework\serializers.py", line 687, in <listcomp>
    self.child.to_representation(item) for item in iterable
    ^^^^^^^^^^^^^^^^^^^^^^^^^^^^^^^^^^
  File "C:\Users\ekad1\PycharmProjects\DjangoProjects\News Portal\venv\Lib\site-packages\rest_framework\serializers.py", line 507, in to_representation
    for field in fields:
  File "C:\Users\ekad1\PycharmProjects\DjangoProjects\News Portal\venv\Lib\site-packages\rest_framework\serializers.py", line 368, in _readable_fields
    for field in self.fields.values():
                 ^^^^^^^^^^^
  File "C:\Users\ekad1\PycharmProjects\DjangoProjects\News Portal\venv\Lib\site-packages\django\utils\functional.py", line 57, in __get__
    res = instance.__dict__[self.name] = self.func(instance)
                                         ^^^^^^^^^^^^^^^^^^^
  File "C:\Users\ekad1\PycharmProjects\DjangoProjects\News Portal\venv\Lib\site-packages\rest_framework\serializers.py", line 356, in fields
    for key, value in self.get_fields().items():
                      ^^^^^^^^^^^^^^^^^
  File "C:\Users\ekad1\PycharmProjects\DjangoProjects\News Portal\venv\Lib\site-packages\rest_framework\serializers.py", line 1076, in get_fields
    field_class, field_kwargs = self.build_field(
                                ^^^^^^^^^^^^^^^^^
  File "C:\Users\ekad1\PycharmProjects\DjangoProjects\News Portal\venv\Lib\site-packages\rest_framework\serializers.py", line 1222, in build_field
    return self.build_unknown_field(field_name, model_class)
           ^^^^^^^^^^^^^^^^^^^^^^^^^^^^^^^^^^^^^^^^^^^^^^^^^
  File "C:\Users\ekad1\PycharmProjects\DjangoProjects\News Portal\venv\Lib\site-packages\rest_framework\serializers.py", line 1340, in build_unknown_field
    raise ImproperlyConfigured(
django.core.exceptions.ImproperlyConfigured: Field name `type` is not valid for model `Post`.
2023-11-04 03:29:37 ERROR "GET /api/articles/ HTTP/1.1" 500 158649 C:\Users\ekad1\PycharmProjects\DjangoProjects\News Portal\venv\Lib\site-packages\django\core\servers\basehttp.py None
2023-11-04 03:45:45 ERROR Internal Server Error: /api/category/ C:\Users\ekad1\PycharmProjects\DjangoProjects\News Portal\venv\Lib\site-packages\django\utils\log.py (<class 'django.core.exceptions.ImproperlyConfigured'>, ImproperlyConfigured('Field name `name` is not valid for model `Category`.'), <traceback object at 0x0000020430A38840>)
Traceback (most recent call last):
  File "C:\Users\ekad1\PycharmProjects\DjangoProjects\News Portal\venv\Lib\site-packages\django\core\handlers\exception.py", line 55, in inner
    response = get_response(request)
               ^^^^^^^^^^^^^^^^^^^^^
  File "C:\Users\ekad1\PycharmProjects\DjangoProjects\News Portal\venv\Lib\site-packages\django\core\handlers\base.py", line 197, in _get_response
    response = wrapped_callback(request, *callback_args, **callback_kwargs)
               ^^^^^^^^^^^^^^^^^^^^^^^^^^^^^^^^^^^^^^^^^^^^^^^^^^^^^^^^^^^^
  File "C:\Users\ekad1\PycharmProjects\DjangoProjects\News Portal\venv\Lib\site-packages\django\views\decorators\csrf.py", line 56, in wrapper_view
    return view_func(*args, **kwargs)
           ^^^^^^^^^^^^^^^^^^^^^^^^^^
  File "C:\Users\ekad1\PycharmProjects\DjangoProjects\News Portal\venv\Lib\site-packages\rest_framework\viewsets.py", line 125, in view
    return self.dispatch(request, *args, **kwargs)
           ^^^^^^^^^^^^^^^^^^^^^^^^^^^^^^^^^^^^^^^
  File "C:\Users\ekad1\PycharmProjects\DjangoProjects\News Portal\venv\Lib\site-packages\rest_framework\views.py", line 509, in dispatch
    response = self.handle_exception(exc)
               ^^^^^^^^^^^^^^^^^^^^^^^^^^
  File "C:\Users\ekad1\PycharmProjects\DjangoProjects\News Portal\venv\Lib\site-packages\rest_framework\views.py", line 469, in handle_exception
    self.raise_uncaught_exception(exc)
  File "C:\Users\ekad1\PycharmProjects\DjangoProjects\News Portal\venv\Lib\site-packages\rest_framework\views.py", line 480, in raise_uncaught_exception
    raise exc
  File "C:\Users\ekad1\PycharmProjects\DjangoProjects\News Portal\venv\Lib\site-packages\rest_framework\views.py", line 506, in dispatch
    response = handler(request, *args, **kwargs)
               ^^^^^^^^^^^^^^^^^^^^^^^^^^^^^^^^^
  File "C:\Users\ekad1\PycharmProjects\DjangoProjects\News Portal\venv\Lib\site-packages\rest_framework\mixins.py", line 46, in list
    return Response(serializer.data)
                    ^^^^^^^^^^^^^^^
  File "C:\Users\ekad1\PycharmProjects\DjangoProjects\News Portal\venv\Lib\site-packages\rest_framework\serializers.py", line 768, in data
    ret = super().data
          ^^^^^^^^^^^^
  File "C:\Users\ekad1\PycharmProjects\DjangoProjects\News Portal\venv\Lib\site-packages\rest_framework\serializers.py", line 253, in data
    self._data = self.to_representation(self.instance)
                 ^^^^^^^^^^^^^^^^^^^^^^^^^^^^^^^^^^^^^
  File "C:\Users\ekad1\PycharmProjects\DjangoProjects\News Portal\venv\Lib\site-packages\rest_framework\serializers.py", line 686, in to_representation
    return [
           ^
  File "C:\Users\ekad1\PycharmProjects\DjangoProjects\News Portal\venv\Lib\site-packages\rest_framework\serializers.py", line 687, in <listcomp>
    self.child.to_representation(item) for item in iterable
    ^^^^^^^^^^^^^^^^^^^^^^^^^^^^^^^^^^
  File "C:\Users\ekad1\PycharmProjects\DjangoProjects\News Portal\venv\Lib\site-packages\rest_framework\serializers.py", line 507, in to_representation
    for field in fields:
  File "C:\Users\ekad1\PycharmProjects\DjangoProjects\News Portal\venv\Lib\site-packages\rest_framework\serializers.py", line 368, in _readable_fields
    for field in self.fields.values():
                 ^^^^^^^^^^^
  File "C:\Users\ekad1\PycharmProjects\DjangoProjects\News Portal\venv\Lib\site-packages\django\utils\functional.py", line 57, in __get__
    res = instance.__dict__[self.name] = self.func(instance)
                                         ^^^^^^^^^^^^^^^^^^^
  File "C:\Users\ekad1\PycharmProjects\DjangoProjects\News Portal\venv\Lib\site-packages\rest_framework\serializers.py", line 356, in fields
    for key, value in self.get_fields().items():
                      ^^^^^^^^^^^^^^^^^
  File "C:\Users\ekad1\PycharmProjects\DjangoProjects\News Portal\venv\Lib\site-packages\rest_framework\serializers.py", line 1076, in get_fields
    field_class, field_kwargs = self.build_field(
                                ^^^^^^^^^^^^^^^^^
  File "C:\Users\ekad1\PycharmProjects\DjangoProjects\News Portal\venv\Lib\site-packages\rest_framework\serializers.py", line 1222, in build_field
    return self.build_unknown_field(field_name, model_class)
           ^^^^^^^^^^^^^^^^^^^^^^^^^^^^^^^^^^^^^^^^^^^^^^^^^
  File "C:\Users\ekad1\PycharmProjects\DjangoProjects\News Portal\venv\Lib\site-packages\rest_framework\serializers.py", line 1340, in build_unknown_field
    raise ImproperlyConfigured(
django.core.exceptions.ImproperlyConfigured: Field name `name` is not valid for model `Category`.
2023-11-04 03:45:45 ERROR "GET /api/category/ HTTP/1.1" 500 155035 C:\Users\ekad1\PycharmProjects\DjangoProjects\News Portal\venv\Lib\site-packages\django\core\servers\basehttp.py None
2023-11-04 15:19:43 ERROR Internal Server Error: /api/articles/ C:\Users\ekad1\PycharmProjects\DjangoProjects\News Portal\venv\Lib\site-packages\django\utils\log.py (<class 'django.core.exceptions.ImproperlyConfigured'>, ImproperlyConfigured('Could not resolve URL for hyperlinked relationship using view name "author-detail". You may have failed to include the related model in your API, or incorrectly configured the `lookup_field` attribute on this field.'), <traceback object at 0x0000029B078AD9C0>)
Traceback (most recent call last):
  File "C:\Users\ekad1\PycharmProjects\DjangoProjects\News Portal\venv\Lib\site-packages\rest_framework\relations.py", line 401, in to_representation
    url = self.get_url(value, self.view_name, request, format)
          ^^^^^^^^^^^^^^^^^^^^^^^^^^^^^^^^^^^^^^^^^^^^^^^^^^^^
  File "C:\Users\ekad1\PycharmProjects\DjangoProjects\News Portal\venv\Lib\site-packages\rest_framework\relations.py", line 339, in get_url
    return self.reverse(view_name, kwargs=kwargs, request=request, format=format)
           ^^^^^^^^^^^^^^^^^^^^^^^^^^^^^^^^^^^^^^^^^^^^^^^^^^^^^^^^^^^^^^^^^^^^^^
  File "C:\Users\ekad1\PycharmProjects\DjangoProjects\News Portal\venv\Lib\site-packages\rest_framework\reverse.py", line 47, in reverse
    url = _reverse(viewname, args, kwargs, request, format, **extra)
          ^^^^^^^^^^^^^^^^^^^^^^^^^^^^^^^^^^^^^^^^^^^^^^^^^^^^^^^^^^
  File "C:\Users\ekad1\PycharmProjects\DjangoProjects\News Portal\venv\Lib\site-packages\rest_framework\reverse.py", line 60, in _reverse
    url = django_reverse(viewname, args=args, kwargs=kwargs, **extra)
          ^^^^^^^^^^^^^^^^^^^^^^^^^^^^^^^^^^^^^^^^^^^^^^^^^^^^^^^^^^^
  File "C:\Users\ekad1\PycharmProjects\DjangoProjects\News Portal\venv\Lib\site-packages\django\urls\base.py", line 88, in reverse
    return resolver._reverse_with_prefix(view, prefix, *args, **kwargs)
           ^^^^^^^^^^^^^^^^^^^^^^^^^^^^^^^^^^^^^^^^^^^^^^^^^^^^^^^^^^^^
  File "C:\Users\ekad1\PycharmProjects\DjangoProjects\News Portal\venv\Lib\site-packages\django\urls\resolvers.py", line 828, in _reverse_with_prefix
    raise NoReverseMatch(msg)
django.urls.exceptions.NoReverseMatch: Reverse for 'author-detail' not found. 'author-detail' is not a valid view function or pattern name.

During handling of the above exception, another exception occurred:

Traceback (most recent call last):
  File "C:\Users\ekad1\PycharmProjects\DjangoProjects\News Portal\venv\Lib\site-packages\django\core\handlers\exception.py", line 55, in inner
    response = get_response(request)
               ^^^^^^^^^^^^^^^^^^^^^
  File "C:\Users\ekad1\PycharmProjects\DjangoProjects\News Portal\venv\Lib\site-packages\django\core\handlers\base.py", line 197, in _get_response
    response = wrapped_callback(request, *callback_args, **callback_kwargs)
               ^^^^^^^^^^^^^^^^^^^^^^^^^^^^^^^^^^^^^^^^^^^^^^^^^^^^^^^^^^^^
  File "C:\Users\ekad1\PycharmProjects\DjangoProjects\News Portal\venv\Lib\site-packages\django\views\decorators\csrf.py", line 56, in wrapper_view
    return view_func(*args, **kwargs)
           ^^^^^^^^^^^^^^^^^^^^^^^^^^
  File "C:\Users\ekad1\PycharmProjects\DjangoProjects\News Portal\venv\Lib\site-packages\rest_framework\viewsets.py", line 125, in view
    return self.dispatch(request, *args, **kwargs)
           ^^^^^^^^^^^^^^^^^^^^^^^^^^^^^^^^^^^^^^^
  File "C:\Users\ekad1\PycharmProjects\DjangoProjects\News Portal\venv\Lib\site-packages\rest_framework\views.py", line 509, in dispatch
    response = self.handle_exception(exc)
               ^^^^^^^^^^^^^^^^^^^^^^^^^^
  File "C:\Users\ekad1\PycharmProjects\DjangoProjects\News Portal\venv\Lib\site-packages\rest_framework\views.py", line 469, in handle_exception
    self.raise_uncaught_exception(exc)
  File "C:\Users\ekad1\PycharmProjects\DjangoProjects\News Portal\venv\Lib\site-packages\rest_framework\views.py", line 480, in raise_uncaught_exception
    raise exc
  File "C:\Users\ekad1\PycharmProjects\DjangoProjects\News Portal\venv\Lib\site-packages\rest_framework\views.py", line 506, in dispatch
    response = handler(request, *args, **kwargs)
               ^^^^^^^^^^^^^^^^^^^^^^^^^^^^^^^^^
  File "C:\Users\ekad1\PycharmProjects\DjangoProjects\News Portal\venv\Lib\site-packages\rest_framework\mixins.py", line 46, in list
    return Response(serializer.data)
                    ^^^^^^^^^^^^^^^
  File "C:\Users\ekad1\PycharmProjects\DjangoProjects\News Portal\venv\Lib\site-packages\rest_framework\serializers.py", line 768, in data
    ret = super().data
          ^^^^^^^^^^^^
  File "C:\Users\ekad1\PycharmProjects\DjangoProjects\News Portal\venv\Lib\site-packages\rest_framework\serializers.py", line 253, in data
    self._data = self.to_representation(self.instance)
                 ^^^^^^^^^^^^^^^^^^^^^^^^^^^^^^^^^^^^^
  File "C:\Users\ekad1\PycharmProjects\DjangoProjects\News Portal\venv\Lib\site-packages\rest_framework\serializers.py", line 686, in to_representation
    return [
           ^
  File "C:\Users\ekad1\PycharmProjects\DjangoProjects\News Portal\venv\Lib\site-packages\rest_framework\serializers.py", line 687, in <listcomp>
    self.child.to_representation(item) for item in iterable
    ^^^^^^^^^^^^^^^^^^^^^^^^^^^^^^^^^^
  File "C:\Users\ekad1\PycharmProjects\DjangoProjects\News Portal\venv\Lib\site-packages\rest_framework\serializers.py", line 522, in to_representation
    ret[field.field_name] = field.to_representation(attribute)
                            ^^^^^^^^^^^^^^^^^^^^^^^^^^^^^^^^^^
  File "C:\Users\ekad1\PycharmProjects\DjangoProjects\News Portal\venv\Lib\site-packages\rest_framework\relations.py", line 416, in to_representation
    raise ImproperlyConfigured(msg % self.view_name)
django.core.exceptions.ImproperlyConfigured: Could not resolve URL for hyperlinked relationship using view name "author-detail". You may have failed to include the related model in your API, or incorrectly configured the `lookup_field` attribute on this field.
2023-11-04 15:19:43 ERROR "GET /api/articles/ HTTP/1.1" 500 170463 C:\Users\ekad1\PycharmProjects\DjangoProjects\News Portal\venv\Lib\site-packages\django\core\servers\basehttp.py None
2023-11-04 15:26:37 ERROR Internal Server Error: /api/articles/ C:\Users\ekad1\PycharmProjects\DjangoProjects\News Portal\venv\Lib\site-packages\django\utils\log.py (<class 'django.core.exceptions.ImproperlyConfigured'>, ImproperlyConfigured('Could not resolve URL for hyperlinked relationship using view name "author-detail". You may have failed to include the related model in your API, or incorrectly configured the `lookup_field` attribute on this field.'), <traceback object at 0x0000029B07735240>)
Traceback (most recent call last):
  File "C:\Users\ekad1\PycharmProjects\DjangoProjects\News Portal\venv\Lib\site-packages\rest_framework\relations.py", line 401, in to_representation
    url = self.get_url(value, self.view_name, request, format)
          ^^^^^^^^^^^^^^^^^^^^^^^^^^^^^^^^^^^^^^^^^^^^^^^^^^^^
  File "C:\Users\ekad1\PycharmProjects\DjangoProjects\News Portal\venv\Lib\site-packages\rest_framework\relations.py", line 339, in get_url
    return self.reverse(view_name, kwargs=kwargs, request=request, format=format)
           ^^^^^^^^^^^^^^^^^^^^^^^^^^^^^^^^^^^^^^^^^^^^^^^^^^^^^^^^^^^^^^^^^^^^^^
  File "C:\Users\ekad1\PycharmProjects\DjangoProjects\News Portal\venv\Lib\site-packages\rest_framework\reverse.py", line 47, in reverse
    url = _reverse(viewname, args, kwargs, request, format, **extra)
          ^^^^^^^^^^^^^^^^^^^^^^^^^^^^^^^^^^^^^^^^^^^^^^^^^^^^^^^^^^
  File "C:\Users\ekad1\PycharmProjects\DjangoProjects\News Portal\venv\Lib\site-packages\rest_framework\reverse.py", line 60, in _reverse
    url = django_reverse(viewname, args=args, kwargs=kwargs, **extra)
          ^^^^^^^^^^^^^^^^^^^^^^^^^^^^^^^^^^^^^^^^^^^^^^^^^^^^^^^^^^^
  File "C:\Users\ekad1\PycharmProjects\DjangoProjects\News Portal\venv\Lib\site-packages\django\urls\base.py", line 88, in reverse
    return resolver._reverse_with_prefix(view, prefix, *args, **kwargs)
           ^^^^^^^^^^^^^^^^^^^^^^^^^^^^^^^^^^^^^^^^^^^^^^^^^^^^^^^^^^^^
  File "C:\Users\ekad1\PycharmProjects\DjangoProjects\News Portal\venv\Lib\site-packages\django\urls\resolvers.py", line 828, in _reverse_with_prefix
    raise NoReverseMatch(msg)
django.urls.exceptions.NoReverseMatch: Reverse for 'author-detail' not found. 'author-detail' is not a valid view function or pattern name.

During handling of the above exception, another exception occurred:

Traceback (most recent call last):
  File "C:\Users\ekad1\PycharmProjects\DjangoProjects\News Portal\venv\Lib\site-packages\django\core\handlers\exception.py", line 55, in inner
    response = get_response(request)
               ^^^^^^^^^^^^^^^^^^^^^
  File "C:\Users\ekad1\PycharmProjects\DjangoProjects\News Portal\venv\Lib\site-packages\django\core\handlers\base.py", line 197, in _get_response
    response = wrapped_callback(request, *callback_args, **callback_kwargs)
               ^^^^^^^^^^^^^^^^^^^^^^^^^^^^^^^^^^^^^^^^^^^^^^^^^^^^^^^^^^^^
  File "C:\Users\ekad1\PycharmProjects\DjangoProjects\News Portal\venv\Lib\site-packages\django\views\decorators\csrf.py", line 56, in wrapper_view
    return view_func(*args, **kwargs)
           ^^^^^^^^^^^^^^^^^^^^^^^^^^
  File "C:\Users\ekad1\PycharmProjects\DjangoProjects\News Portal\venv\Lib\site-packages\rest_framework\viewsets.py", line 125, in view
    return self.dispatch(request, *args, **kwargs)
           ^^^^^^^^^^^^^^^^^^^^^^^^^^^^^^^^^^^^^^^
  File "C:\Users\ekad1\PycharmProjects\DjangoProjects\News Portal\venv\Lib\site-packages\rest_framework\views.py", line 509, in dispatch
    response = self.handle_exception(exc)
               ^^^^^^^^^^^^^^^^^^^^^^^^^^
  File "C:\Users\ekad1\PycharmProjects\DjangoProjects\News Portal\venv\Lib\site-packages\rest_framework\views.py", line 469, in handle_exception
    self.raise_uncaught_exception(exc)
  File "C:\Users\ekad1\PycharmProjects\DjangoProjects\News Portal\venv\Lib\site-packages\rest_framework\views.py", line 480, in raise_uncaught_exception
    raise exc
  File "C:\Users\ekad1\PycharmProjects\DjangoProjects\News Portal\venv\Lib\site-packages\rest_framework\views.py", line 506, in dispatch
    response = handler(request, *args, **kwargs)
               ^^^^^^^^^^^^^^^^^^^^^^^^^^^^^^^^^
  File "C:\Users\ekad1\PycharmProjects\DjangoProjects\News Portal\venv\Lib\site-packages\rest_framework\mixins.py", line 46, in list
    return Response(serializer.data)
                    ^^^^^^^^^^^^^^^
  File "C:\Users\ekad1\PycharmProjects\DjangoProjects\News Portal\venv\Lib\site-packages\rest_framework\serializers.py", line 768, in data
    ret = super().data
          ^^^^^^^^^^^^
  File "C:\Users\ekad1\PycharmProjects\DjangoProjects\News Portal\venv\Lib\site-packages\rest_framework\serializers.py", line 253, in data
    self._data = self.to_representation(self.instance)
                 ^^^^^^^^^^^^^^^^^^^^^^^^^^^^^^^^^^^^^
  File "C:\Users\ekad1\PycharmProjects\DjangoProjects\News Portal\venv\Lib\site-packages\rest_framework\serializers.py", line 686, in to_representation
    return [
           ^
  File "C:\Users\ekad1\PycharmProjects\DjangoProjects\News Portal\venv\Lib\site-packages\rest_framework\serializers.py", line 687, in <listcomp>
    self.child.to_representation(item) for item in iterable
    ^^^^^^^^^^^^^^^^^^^^^^^^^^^^^^^^^^
  File "C:\Users\ekad1\PycharmProjects\DjangoProjects\News Portal\venv\Lib\site-packages\rest_framework\serializers.py", line 522, in to_representation
    ret[field.field_name] = field.to_representation(attribute)
                            ^^^^^^^^^^^^^^^^^^^^^^^^^^^^^^^^^^
  File "C:\Users\ekad1\PycharmProjects\DjangoProjects\News Portal\venv\Lib\site-packages\rest_framework\relations.py", line 416, in to_representation
    raise ImproperlyConfigured(msg % self.view_name)
django.core.exceptions.ImproperlyConfigured: Could not resolve URL for hyperlinked relationship using view name "author-detail". You may have failed to include the related model in your API, or incorrectly configured the `lookup_field` attribute on this field.
2023-11-04 15:26:37 ERROR "GET /api/articles/ HTTP/1.1" 500 170463 C:\Users\ekad1\PycharmProjects\DjangoProjects\News Portal\venv\Lib\site-packages\django\core\servers\basehttp.py None
2023-11-04 15:29:27 ERROR Internal Server Error: /api/news/ C:\Users\ekad1\PycharmProjects\DjangoProjects\News Portal\venv\Lib\site-packages\django\utils\log.py (<class 'django.core.exceptions.ImproperlyConfigured'>, ImproperlyConfigured('Could not resolve URL for hyperlinked relationship using view name "author-detail". You may have failed to include the related model in your API, or incorrectly configured the `lookup_field` attribute on this field.'), <traceback object at 0x0000021E7827B480>)
Traceback (most recent call last):
  File "C:\Users\ekad1\PycharmProjects\DjangoProjects\News Portal\venv\Lib\site-packages\rest_framework\relations.py", line 401, in to_representation
    url = self.get_url(value, self.view_name, request, format)
          ^^^^^^^^^^^^^^^^^^^^^^^^^^^^^^^^^^^^^^^^^^^^^^^^^^^^
  File "C:\Users\ekad1\PycharmProjects\DjangoProjects\News Portal\venv\Lib\site-packages\rest_framework\relations.py", line 339, in get_url
    return self.reverse(view_name, kwargs=kwargs, request=request, format=format)
           ^^^^^^^^^^^^^^^^^^^^^^^^^^^^^^^^^^^^^^^^^^^^^^^^^^^^^^^^^^^^^^^^^^^^^^
  File "C:\Users\ekad1\PycharmProjects\DjangoProjects\News Portal\venv\Lib\site-packages\rest_framework\reverse.py", line 47, in reverse
    url = _reverse(viewname, args, kwargs, request, format, **extra)
          ^^^^^^^^^^^^^^^^^^^^^^^^^^^^^^^^^^^^^^^^^^^^^^^^^^^^^^^^^^
  File "C:\Users\ekad1\PycharmProjects\DjangoProjects\News Portal\venv\Lib\site-packages\rest_framework\reverse.py", line 60, in _reverse
    url = django_reverse(viewname, args=args, kwargs=kwargs, **extra)
          ^^^^^^^^^^^^^^^^^^^^^^^^^^^^^^^^^^^^^^^^^^^^^^^^^^^^^^^^^^^
  File "C:\Users\ekad1\PycharmProjects\DjangoProjects\News Portal\venv\Lib\site-packages\django\urls\base.py", line 88, in reverse
    return resolver._reverse_with_prefix(view, prefix, *args, **kwargs)
           ^^^^^^^^^^^^^^^^^^^^^^^^^^^^^^^^^^^^^^^^^^^^^^^^^^^^^^^^^^^^
  File "C:\Users\ekad1\PycharmProjects\DjangoProjects\News Portal\venv\Lib\site-packages\django\urls\resolvers.py", line 828, in _reverse_with_prefix
    raise NoReverseMatch(msg)
django.urls.exceptions.NoReverseMatch: Reverse for 'author-detail' not found. 'author-detail' is not a valid view function or pattern name.

During handling of the above exception, another exception occurred:

Traceback (most recent call last):
  File "C:\Users\ekad1\PycharmProjects\DjangoProjects\News Portal\venv\Lib\site-packages\django\core\handlers\exception.py", line 55, in inner
    response = get_response(request)
               ^^^^^^^^^^^^^^^^^^^^^
  File "C:\Users\ekad1\PycharmProjects\DjangoProjects\News Portal\venv\Lib\site-packages\django\core\handlers\base.py", line 197, in _get_response
    response = wrapped_callback(request, *callback_args, **callback_kwargs)
               ^^^^^^^^^^^^^^^^^^^^^^^^^^^^^^^^^^^^^^^^^^^^^^^^^^^^^^^^^^^^
  File "C:\Users\ekad1\PycharmProjects\DjangoProjects\News Portal\venv\Lib\site-packages\django\views\decorators\csrf.py", line 56, in wrapper_view
    return view_func(*args, **kwargs)
           ^^^^^^^^^^^^^^^^^^^^^^^^^^
  File "C:\Users\ekad1\PycharmProjects\DjangoProjects\News Portal\venv\Lib\site-packages\rest_framework\viewsets.py", line 125, in view
    return self.dispatch(request, *args, **kwargs)
           ^^^^^^^^^^^^^^^^^^^^^^^^^^^^^^^^^^^^^^^
  File "C:\Users\ekad1\PycharmProjects\DjangoProjects\News Portal\venv\Lib\site-packages\rest_framework\views.py", line 509, in dispatch
    response = self.handle_exception(exc)
               ^^^^^^^^^^^^^^^^^^^^^^^^^^
  File "C:\Users\ekad1\PycharmProjects\DjangoProjects\News Portal\venv\Lib\site-packages\rest_framework\views.py", line 469, in handle_exception
    self.raise_uncaught_exception(exc)
  File "C:\Users\ekad1\PycharmProjects\DjangoProjects\News Portal\venv\Lib\site-packages\rest_framework\views.py", line 480, in raise_uncaught_exception
    raise exc
  File "C:\Users\ekad1\PycharmProjects\DjangoProjects\News Portal\venv\Lib\site-packages\rest_framework\views.py", line 506, in dispatch
    response = handler(request, *args, **kwargs)
               ^^^^^^^^^^^^^^^^^^^^^^^^^^^^^^^^^
  File "C:\Users\ekad1\PycharmProjects\DjangoProjects\News Portal\venv\Lib\site-packages\rest_framework\mixins.py", line 46, in list
    return Response(serializer.data)
                    ^^^^^^^^^^^^^^^
  File "C:\Users\ekad1\PycharmProjects\DjangoProjects\News Portal\venv\Lib\site-packages\rest_framework\serializers.py", line 768, in data
    ret = super().data
          ^^^^^^^^^^^^
  File "C:\Users\ekad1\PycharmProjects\DjangoProjects\News Portal\venv\Lib\site-packages\rest_framework\serializers.py", line 253, in data
    self._data = self.to_representation(self.instance)
                 ^^^^^^^^^^^^^^^^^^^^^^^^^^^^^^^^^^^^^
  File "C:\Users\ekad1\PycharmProjects\DjangoProjects\News Portal\venv\Lib\site-packages\rest_framework\serializers.py", line 686, in to_representation
    return [
           ^
  File "C:\Users\ekad1\PycharmProjects\DjangoProjects\News Portal\venv\Lib\site-packages\rest_framework\serializers.py", line 687, in <listcomp>
    self.child.to_representation(item) for item in iterable
    ^^^^^^^^^^^^^^^^^^^^^^^^^^^^^^^^^^
  File "C:\Users\ekad1\PycharmProjects\DjangoProjects\News Portal\venv\Lib\site-packages\rest_framework\serializers.py", line 522, in to_representation
    ret[field.field_name] = field.to_representation(attribute)
                            ^^^^^^^^^^^^^^^^^^^^^^^^^^^^^^^^^^
  File "C:\Users\ekad1\PycharmProjects\DjangoProjects\News Portal\venv\Lib\site-packages\rest_framework\relations.py", line 416, in to_representation
    raise ImproperlyConfigured(msg % self.view_name)
django.core.exceptions.ImproperlyConfigured: Could not resolve URL for hyperlinked relationship using view name "author-detail". You may have failed to include the related model in your API, or incorrectly configured the `lookup_field` attribute on this field.
2023-11-04 15:29:27 ERROR "GET /api/news/ HTTP/1.1" 500 170247 C:\Users\ekad1\PycharmProjects\DjangoProjects\News Portal\venv\Lib\site-packages\django\core\servers\basehttp.py None
2023-11-04 15:30:42 ERROR Internal Server Error: /api/news/ C:\Users\ekad1\PycharmProjects\DjangoProjects\News Portal\venv\Lib\site-packages\django\utils\log.py (<class 'django.core.exceptions.ImproperlyConfigured'>, ImproperlyConfigured('Could not resolve URL for hyperlinked relationship using view name "author-detail". You may have failed to include the related model in your API, or incorrectly configured the `lookup_field` attribute on this field.'), <traceback object at 0x0000021E7815F580>)
Traceback (most recent call last):
  File "C:\Users\ekad1\PycharmProjects\DjangoProjects\News Portal\venv\Lib\site-packages\rest_framework\relations.py", line 401, in to_representation
    url = self.get_url(value, self.view_name, request, format)
          ^^^^^^^^^^^^^^^^^^^^^^^^^^^^^^^^^^^^^^^^^^^^^^^^^^^^
  File "C:\Users\ekad1\PycharmProjects\DjangoProjects\News Portal\venv\Lib\site-packages\rest_framework\relations.py", line 339, in get_url
    return self.reverse(view_name, kwargs=kwargs, request=request, format=format)
           ^^^^^^^^^^^^^^^^^^^^^^^^^^^^^^^^^^^^^^^^^^^^^^^^^^^^^^^^^^^^^^^^^^^^^^
  File "C:\Users\ekad1\PycharmProjects\DjangoProjects\News Portal\venv\Lib\site-packages\rest_framework\reverse.py", line 47, in reverse
    url = _reverse(viewname, args, kwargs, request, format, **extra)
          ^^^^^^^^^^^^^^^^^^^^^^^^^^^^^^^^^^^^^^^^^^^^^^^^^^^^^^^^^^
  File "C:\Users\ekad1\PycharmProjects\DjangoProjects\News Portal\venv\Lib\site-packages\rest_framework\reverse.py", line 60, in _reverse
    url = django_reverse(viewname, args=args, kwargs=kwargs, **extra)
          ^^^^^^^^^^^^^^^^^^^^^^^^^^^^^^^^^^^^^^^^^^^^^^^^^^^^^^^^^^^
  File "C:\Users\ekad1\PycharmProjects\DjangoProjects\News Portal\venv\Lib\site-packages\django\urls\base.py", line 88, in reverse
    return resolver._reverse_with_prefix(view, prefix, *args, **kwargs)
           ^^^^^^^^^^^^^^^^^^^^^^^^^^^^^^^^^^^^^^^^^^^^^^^^^^^^^^^^^^^^
  File "C:\Users\ekad1\PycharmProjects\DjangoProjects\News Portal\venv\Lib\site-packages\django\urls\resolvers.py", line 828, in _reverse_with_prefix
    raise NoReverseMatch(msg)
django.urls.exceptions.NoReverseMatch: Reverse for 'author-detail' not found. 'author-detail' is not a valid view function or pattern name.

During handling of the above exception, another exception occurred:

Traceback (most recent call last):
  File "C:\Users\ekad1\PycharmProjects\DjangoProjects\News Portal\venv\Lib\site-packages\django\core\handlers\exception.py", line 55, in inner
    response = get_response(request)
               ^^^^^^^^^^^^^^^^^^^^^
  File "C:\Users\ekad1\PycharmProjects\DjangoProjects\News Portal\venv\Lib\site-packages\django\core\handlers\base.py", line 197, in _get_response
    response = wrapped_callback(request, *callback_args, **callback_kwargs)
               ^^^^^^^^^^^^^^^^^^^^^^^^^^^^^^^^^^^^^^^^^^^^^^^^^^^^^^^^^^^^
  File "C:\Users\ekad1\PycharmProjects\DjangoProjects\News Portal\venv\Lib\site-packages\django\views\decorators\csrf.py", line 56, in wrapper_view
    return view_func(*args, **kwargs)
           ^^^^^^^^^^^^^^^^^^^^^^^^^^
  File "C:\Users\ekad1\PycharmProjects\DjangoProjects\News Portal\venv\Lib\site-packages\rest_framework\viewsets.py", line 125, in view
    return self.dispatch(request, *args, **kwargs)
           ^^^^^^^^^^^^^^^^^^^^^^^^^^^^^^^^^^^^^^^
  File "C:\Users\ekad1\PycharmProjects\DjangoProjects\News Portal\venv\Lib\site-packages\rest_framework\views.py", line 509, in dispatch
    response = self.handle_exception(exc)
               ^^^^^^^^^^^^^^^^^^^^^^^^^^
  File "C:\Users\ekad1\PycharmProjects\DjangoProjects\News Portal\venv\Lib\site-packages\rest_framework\views.py", line 469, in handle_exception
    self.raise_uncaught_exception(exc)
  File "C:\Users\ekad1\PycharmProjects\DjangoProjects\News Portal\venv\Lib\site-packages\rest_framework\views.py", line 480, in raise_uncaught_exception
    raise exc
  File "C:\Users\ekad1\PycharmProjects\DjangoProjects\News Portal\venv\Lib\site-packages\rest_framework\views.py", line 506, in dispatch
    response = handler(request, *args, **kwargs)
               ^^^^^^^^^^^^^^^^^^^^^^^^^^^^^^^^^
  File "C:\Users\ekad1\PycharmProjects\DjangoProjects\News Portal\venv\Lib\site-packages\rest_framework\mixins.py", line 46, in list
    return Response(serializer.data)
                    ^^^^^^^^^^^^^^^
  File "C:\Users\ekad1\PycharmProjects\DjangoProjects\News Portal\venv\Lib\site-packages\rest_framework\serializers.py", line 768, in data
    ret = super().data
          ^^^^^^^^^^^^
  File "C:\Users\ekad1\PycharmProjects\DjangoProjects\News Portal\venv\Lib\site-packages\rest_framework\serializers.py", line 253, in data
    self._data = self.to_representation(self.instance)
                 ^^^^^^^^^^^^^^^^^^^^^^^^^^^^^^^^^^^^^
  File "C:\Users\ekad1\PycharmProjects\DjangoProjects\News Portal\venv\Lib\site-packages\rest_framework\serializers.py", line 686, in to_representation
    return [
           ^
  File "C:\Users\ekad1\PycharmProjects\DjangoProjects\News Portal\venv\Lib\site-packages\rest_framework\serializers.py", line 687, in <listcomp>
    self.child.to_representation(item) for item in iterable
    ^^^^^^^^^^^^^^^^^^^^^^^^^^^^^^^^^^
  File "C:\Users\ekad1\PycharmProjects\DjangoProjects\News Portal\venv\Lib\site-packages\rest_framework\serializers.py", line 522, in to_representation
    ret[field.field_name] = field.to_representation(attribute)
                            ^^^^^^^^^^^^^^^^^^^^^^^^^^^^^^^^^^
  File "C:\Users\ekad1\PycharmProjects\DjangoProjects\News Portal\venv\Lib\site-packages\rest_framework\relations.py", line 416, in to_representation
    raise ImproperlyConfigured(msg % self.view_name)
django.core.exceptions.ImproperlyConfigured: Could not resolve URL for hyperlinked relationship using view name "author-detail". You may have failed to include the related model in your API, or incorrectly configured the `lookup_field` attribute on this field.
2023-11-04 15:30:42 ERROR "GET /api/news/ HTTP/1.1" 500 170247 C:\Users\ekad1\PycharmProjects\DjangoProjects\News Portal\venv\Lib\site-packages\django\core\servers\basehttp.py None
2023-11-04 15:33:10 ERROR Internal Server Error: /api/news/ C:\Users\ekad1\PycharmProjects\DjangoProjects\News Portal\venv\Lib\site-packages\django\utils\log.py (<class 'django.core.exceptions.ImproperlyConfigured'>, ImproperlyConfigured('Could not resolve URL for hyperlinked relationship using view name "author-detail". You may have failed to include the related model in your API, or incorrectly configured the `lookup_field` attribute on this field.'), <traceback object at 0x0000021E780CE340>)
Traceback (most recent call last):
  File "C:\Users\ekad1\PycharmProjects\DjangoProjects\News Portal\venv\Lib\site-packages\rest_framework\relations.py", line 401, in to_representation
    url = self.get_url(value, self.view_name, request, format)
          ^^^^^^^^^^^^^^^^^^^^^^^^^^^^^^^^^^^^^^^^^^^^^^^^^^^^
  File "C:\Users\ekad1\PycharmProjects\DjangoProjects\News Portal\venv\Lib\site-packages\rest_framework\relations.py", line 339, in get_url
    return self.reverse(view_name, kwargs=kwargs, request=request, format=format)
           ^^^^^^^^^^^^^^^^^^^^^^^^^^^^^^^^^^^^^^^^^^^^^^^^^^^^^^^^^^^^^^^^^^^^^^
  File "C:\Users\ekad1\PycharmProjects\DjangoProjects\News Portal\venv\Lib\site-packages\rest_framework\reverse.py", line 47, in reverse
    url = _reverse(viewname, args, kwargs, request, format, **extra)
          ^^^^^^^^^^^^^^^^^^^^^^^^^^^^^^^^^^^^^^^^^^^^^^^^^^^^^^^^^^
  File "C:\Users\ekad1\PycharmProjects\DjangoProjects\News Portal\venv\Lib\site-packages\rest_framework\reverse.py", line 60, in _reverse
    url = django_reverse(viewname, args=args, kwargs=kwargs, **extra)
          ^^^^^^^^^^^^^^^^^^^^^^^^^^^^^^^^^^^^^^^^^^^^^^^^^^^^^^^^^^^
  File "C:\Users\ekad1\PycharmProjects\DjangoProjects\News Portal\venv\Lib\site-packages\django\urls\base.py", line 88, in reverse
    return resolver._reverse_with_prefix(view, prefix, *args, **kwargs)
           ^^^^^^^^^^^^^^^^^^^^^^^^^^^^^^^^^^^^^^^^^^^^^^^^^^^^^^^^^^^^
  File "C:\Users\ekad1\PycharmProjects\DjangoProjects\News Portal\venv\Lib\site-packages\django\urls\resolvers.py", line 828, in _reverse_with_prefix
    raise NoReverseMatch(msg)
django.urls.exceptions.NoReverseMatch: Reverse for 'author-detail' not found. 'author-detail' is not a valid view function or pattern name.

During handling of the above exception, another exception occurred:

Traceback (most recent call last):
  File "C:\Users\ekad1\PycharmProjects\DjangoProjects\News Portal\venv\Lib\site-packages\django\core\handlers\exception.py", line 55, in inner
    response = get_response(request)
               ^^^^^^^^^^^^^^^^^^^^^
  File "C:\Users\ekad1\PycharmProjects\DjangoProjects\News Portal\venv\Lib\site-packages\django\core\handlers\base.py", line 197, in _get_response
    response = wrapped_callback(request, *callback_args, **callback_kwargs)
               ^^^^^^^^^^^^^^^^^^^^^^^^^^^^^^^^^^^^^^^^^^^^^^^^^^^^^^^^^^^^
  File "C:\Users\ekad1\PycharmProjects\DjangoProjects\News Portal\venv\Lib\site-packages\django\views\decorators\csrf.py", line 56, in wrapper_view
    return view_func(*args, **kwargs)
           ^^^^^^^^^^^^^^^^^^^^^^^^^^
  File "C:\Users\ekad1\PycharmProjects\DjangoProjects\News Portal\venv\Lib\site-packages\rest_framework\viewsets.py", line 125, in view
    return self.dispatch(request, *args, **kwargs)
           ^^^^^^^^^^^^^^^^^^^^^^^^^^^^^^^^^^^^^^^
  File "C:\Users\ekad1\PycharmProjects\DjangoProjects\News Portal\venv\Lib\site-packages\rest_framework\views.py", line 509, in dispatch
    response = self.handle_exception(exc)
               ^^^^^^^^^^^^^^^^^^^^^^^^^^
  File "C:\Users\ekad1\PycharmProjects\DjangoProjects\News Portal\venv\Lib\site-packages\rest_framework\views.py", line 469, in handle_exception
    self.raise_uncaught_exception(exc)
  File "C:\Users\ekad1\PycharmProjects\DjangoProjects\News Portal\venv\Lib\site-packages\rest_framework\views.py", line 480, in raise_uncaught_exception
    raise exc
  File "C:\Users\ekad1\PycharmProjects\DjangoProjects\News Portal\venv\Lib\site-packages\rest_framework\views.py", line 506, in dispatch
    response = handler(request, *args, **kwargs)
               ^^^^^^^^^^^^^^^^^^^^^^^^^^^^^^^^^
  File "C:\Users\ekad1\PycharmProjects\DjangoProjects\News Portal\venv\Lib\site-packages\rest_framework\mixins.py", line 46, in list
    return Response(serializer.data)
                    ^^^^^^^^^^^^^^^
  File "C:\Users\ekad1\PycharmProjects\DjangoProjects\News Portal\venv\Lib\site-packages\rest_framework\serializers.py", line 768, in data
    ret = super().data
          ^^^^^^^^^^^^
  File "C:\Users\ekad1\PycharmProjects\DjangoProjects\News Portal\venv\Lib\site-packages\rest_framework\serializers.py", line 253, in data
    self._data = self.to_representation(self.instance)
                 ^^^^^^^^^^^^^^^^^^^^^^^^^^^^^^^^^^^^^
  File "C:\Users\ekad1\PycharmProjects\DjangoProjects\News Portal\venv\Lib\site-packages\rest_framework\serializers.py", line 686, in to_representation
    return [
           ^
  File "C:\Users\ekad1\PycharmProjects\DjangoProjects\News Portal\venv\Lib\site-packages\rest_framework\serializers.py", line 687, in <listcomp>
    self.child.to_representation(item) for item in iterable
    ^^^^^^^^^^^^^^^^^^^^^^^^^^^^^^^^^^
  File "C:\Users\ekad1\PycharmProjects\DjangoProjects\News Portal\venv\Lib\site-packages\rest_framework\serializers.py", line 522, in to_representation
    ret[field.field_name] = field.to_representation(attribute)
                            ^^^^^^^^^^^^^^^^^^^^^^^^^^^^^^^^^^
  File "C:\Users\ekad1\PycharmProjects\DjangoProjects\News Portal\venv\Lib\site-packages\rest_framework\relations.py", line 416, in to_representation
    raise ImproperlyConfigured(msg % self.view_name)
django.core.exceptions.ImproperlyConfigured: Could not resolve URL for hyperlinked relationship using view name "author-detail". You may have failed to include the related model in your API, or incorrectly configured the `lookup_field` attribute on this field.
2023-11-04 15:33:10 ERROR "GET /api/news/ HTTP/1.1" 500 170247 C:\Users\ekad1\PycharmProjects\DjangoProjects\News Portal\venv\Lib\site-packages\django\core\servers\basehttp.py None
2023-11-04 15:38:28 ERROR Internal Server Error: /api/news/ C:\Users\ekad1\PycharmProjects\DjangoProjects\News Portal\venv\Lib\site-packages\django\utils\log.py (<class 'django.core.exceptions.ImproperlyConfigured'>, ImproperlyConfigured('Field name `post_author__author_user` is not valid for model `Post`.'), <traceback object at 0x0000028D683A5E40>)
Traceback (most recent call last):
  File "C:\Users\ekad1\PycharmProjects\DjangoProjects\News Portal\venv\Lib\site-packages\django\core\handlers\exception.py", line 55, in inner
    response = get_response(request)
               ^^^^^^^^^^^^^^^^^^^^^
  File "C:\Users\ekad1\PycharmProjects\DjangoProjects\News Portal\venv\Lib\site-packages\django\core\handlers\base.py", line 197, in _get_response
    response = wrapped_callback(request, *callback_args, **callback_kwargs)
               ^^^^^^^^^^^^^^^^^^^^^^^^^^^^^^^^^^^^^^^^^^^^^^^^^^^^^^^^^^^^
  File "C:\Users\ekad1\PycharmProjects\DjangoProjects\News Portal\venv\Lib\site-packages\django\views\decorators\csrf.py", line 56, in wrapper_view
    return view_func(*args, **kwargs)
           ^^^^^^^^^^^^^^^^^^^^^^^^^^
  File "C:\Users\ekad1\PycharmProjects\DjangoProjects\News Portal\venv\Lib\site-packages\rest_framework\viewsets.py", line 125, in view
    return self.dispatch(request, *args, **kwargs)
           ^^^^^^^^^^^^^^^^^^^^^^^^^^^^^^^^^^^^^^^
  File "C:\Users\ekad1\PycharmProjects\DjangoProjects\News Portal\venv\Lib\site-packages\rest_framework\views.py", line 509, in dispatch
    response = self.handle_exception(exc)
               ^^^^^^^^^^^^^^^^^^^^^^^^^^
  File "C:\Users\ekad1\PycharmProjects\DjangoProjects\News Portal\venv\Lib\site-packages\rest_framework\views.py", line 469, in handle_exception
    self.raise_uncaught_exception(exc)
  File "C:\Users\ekad1\PycharmProjects\DjangoProjects\News Portal\venv\Lib\site-packages\rest_framework\views.py", line 480, in raise_uncaught_exception
    raise exc
  File "C:\Users\ekad1\PycharmProjects\DjangoProjects\News Portal\venv\Lib\site-packages\rest_framework\views.py", line 506, in dispatch
    response = handler(request, *args, **kwargs)
               ^^^^^^^^^^^^^^^^^^^^^^^^^^^^^^^^^
  File "C:\Users\ekad1\PycharmProjects\DjangoProjects\News Portal\venv\Lib\site-packages\rest_framework\mixins.py", line 46, in list
    return Response(serializer.data)
                    ^^^^^^^^^^^^^^^
  File "C:\Users\ekad1\PycharmProjects\DjangoProjects\News Portal\venv\Lib\site-packages\rest_framework\serializers.py", line 768, in data
    ret = super().data
          ^^^^^^^^^^^^
  File "C:\Users\ekad1\PycharmProjects\DjangoProjects\News Portal\venv\Lib\site-packages\rest_framework\serializers.py", line 253, in data
    self._data = self.to_representation(self.instance)
                 ^^^^^^^^^^^^^^^^^^^^^^^^^^^^^^^^^^^^^
  File "C:\Users\ekad1\PycharmProjects\DjangoProjects\News Portal\venv\Lib\site-packages\rest_framework\serializers.py", line 686, in to_representation
    return [
           ^
  File "C:\Users\ekad1\PycharmProjects\DjangoProjects\News Portal\venv\Lib\site-packages\rest_framework\serializers.py", line 687, in <listcomp>
    self.child.to_representation(item) for item in iterable
    ^^^^^^^^^^^^^^^^^^^^^^^^^^^^^^^^^^
  File "C:\Users\ekad1\PycharmProjects\DjangoProjects\News Portal\venv\Lib\site-packages\rest_framework\serializers.py", line 507, in to_representation
    for field in fields:
  File "C:\Users\ekad1\PycharmProjects\DjangoProjects\News Portal\venv\Lib\site-packages\rest_framework\serializers.py", line 368, in _readable_fields
    for field in self.fields.values():
                 ^^^^^^^^^^^
  File "C:\Users\ekad1\PycharmProjects\DjangoProjects\News Portal\venv\Lib\site-packages\django\utils\functional.py", line 57, in __get__
    res = instance.__dict__[self.name] = self.func(instance)
                                         ^^^^^^^^^^^^^^^^^^^
  File "C:\Users\ekad1\PycharmProjects\DjangoProjects\News Portal\venv\Lib\site-packages\rest_framework\serializers.py", line 356, in fields
    for key, value in self.get_fields().items():
                      ^^^^^^^^^^^^^^^^^
  File "C:\Users\ekad1\PycharmProjects\DjangoProjects\News Portal\venv\Lib\site-packages\rest_framework\serializers.py", line 1076, in get_fields
    field_class, field_kwargs = self.build_field(
                                ^^^^^^^^^^^^^^^^^
  File "C:\Users\ekad1\PycharmProjects\DjangoProjects\News Portal\venv\Lib\site-packages\rest_framework\serializers.py", line 1222, in build_field
    return self.build_unknown_field(field_name, model_class)
           ^^^^^^^^^^^^^^^^^^^^^^^^^^^^^^^^^^^^^^^^^^^^^^^^^
  File "C:\Users\ekad1\PycharmProjects\DjangoProjects\News Portal\venv\Lib\site-packages\rest_framework\serializers.py", line 1340, in build_unknown_field
    raise ImproperlyConfigured(
django.core.exceptions.ImproperlyConfigured: Field name `post_author__author_user` is not valid for model `Post`.
2023-11-04 15:38:28 ERROR "GET /api/news/ HTTP/1.1" 500 159576 C:\Users\ekad1\PycharmProjects\DjangoProjects\News Portal\venv\Lib\site-packages\django\core\servers\basehttp.py None
2023-11-04 15:47:02 ERROR Internal Server Error: /api/news/ C:\Users\ekad1\PycharmProjects\DjangoProjects\News Portal\venv\Lib\site-packages\django\utils\log.py (<class 'AssertionError'>, AssertionError(("Creating a ModelSerializer without either the 'fields' attribute or the 'exclude' attribute has been deprecated since 3.3.0, and is now disallowed. Add an explicit fields = '__all__' to the NewsSerializer serializer.",)), <traceback object at 0x000001762AE48680>)
Traceback (most recent call last):
  File "C:\Users\ekad1\PycharmProjects\DjangoProjects\News Portal\venv\Lib\site-packages\django\core\handlers\exception.py", line 55, in inner
    response = get_response(request)
               ^^^^^^^^^^^^^^^^^^^^^
  File "C:\Users\ekad1\PycharmProjects\DjangoProjects\News Portal\venv\Lib\site-packages\django\core\handlers\base.py", line 197, in _get_response
    response = wrapped_callback(request, *callback_args, **callback_kwargs)
               ^^^^^^^^^^^^^^^^^^^^^^^^^^^^^^^^^^^^^^^^^^^^^^^^^^^^^^^^^^^^
  File "C:\Users\ekad1\PycharmProjects\DjangoProjects\News Portal\venv\Lib\site-packages\django\views\decorators\csrf.py", line 56, in wrapper_view
    return view_func(*args, **kwargs)
           ^^^^^^^^^^^^^^^^^^^^^^^^^^
  File "C:\Users\ekad1\PycharmProjects\DjangoProjects\News Portal\venv\Lib\site-packages\rest_framework\viewsets.py", line 125, in view
    return self.dispatch(request, *args, **kwargs)
           ^^^^^^^^^^^^^^^^^^^^^^^^^^^^^^^^^^^^^^^
  File "C:\Users\ekad1\PycharmProjects\DjangoProjects\News Portal\venv\Lib\site-packages\rest_framework\views.py", line 509, in dispatch
    response = self.handle_exception(exc)
               ^^^^^^^^^^^^^^^^^^^^^^^^^^
  File "C:\Users\ekad1\PycharmProjects\DjangoProjects\News Portal\venv\Lib\site-packages\rest_framework\views.py", line 469, in handle_exception
    self.raise_uncaught_exception(exc)
  File "C:\Users\ekad1\PycharmProjects\DjangoProjects\News Portal\venv\Lib\site-packages\rest_framework\views.py", line 480, in raise_uncaught_exception
    raise exc
  File "C:\Users\ekad1\PycharmProjects\DjangoProjects\News Portal\venv\Lib\site-packages\rest_framework\views.py", line 506, in dispatch
    response = handler(request, *args, **kwargs)
               ^^^^^^^^^^^^^^^^^^^^^^^^^^^^^^^^^
  File "C:\Users\ekad1\PycharmProjects\DjangoProjects\News Portal\venv\Lib\site-packages\rest_framework\mixins.py", line 46, in list
    return Response(serializer.data)
                    ^^^^^^^^^^^^^^^
  File "C:\Users\ekad1\PycharmProjects\DjangoProjects\News Portal\venv\Lib\site-packages\rest_framework\serializers.py", line 768, in data
    ret = super().data
          ^^^^^^^^^^^^
  File "C:\Users\ekad1\PycharmProjects\DjangoProjects\News Portal\venv\Lib\site-packages\rest_framework\serializers.py", line 253, in data
    self._data = self.to_representation(self.instance)
                 ^^^^^^^^^^^^^^^^^^^^^^^^^^^^^^^^^^^^^
  File "C:\Users\ekad1\PycharmProjects\DjangoProjects\News Portal\venv\Lib\site-packages\rest_framework\serializers.py", line 686, in to_representation
    return [
           ^
  File "C:\Users\ekad1\PycharmProjects\DjangoProjects\News Portal\venv\Lib\site-packages\rest_framework\serializers.py", line 687, in <listcomp>
    self.child.to_representation(item) for item in iterable
    ^^^^^^^^^^^^^^^^^^^^^^^^^^^^^^^^^^
  File "C:\Users\ekad1\PycharmProjects\DjangoProjects\News Portal\venv\Lib\site-packages\rest_framework\serializers.py", line 507, in to_representation
    for field in fields:
  File "C:\Users\ekad1\PycharmProjects\DjangoProjects\News Portal\venv\Lib\site-packages\rest_framework\serializers.py", line 368, in _readable_fields
    for field in self.fields.values():
                 ^^^^^^^^^^^
  File "C:\Users\ekad1\PycharmProjects\DjangoProjects\News Portal\venv\Lib\site-packages\django\utils\functional.py", line 57, in __get__
    res = instance.__dict__[self.name] = self.func(instance)
                                         ^^^^^^^^^^^^^^^^^^^
  File "C:\Users\ekad1\PycharmProjects\DjangoProjects\News Portal\venv\Lib\site-packages\rest_framework\serializers.py", line 356, in fields
    for key, value in self.get_fields().items():
                      ^^^^^^^^^^^^^^^^^
  File "C:\Users\ekad1\PycharmProjects\DjangoProjects\News Portal\venv\Lib\site-packages\rest_framework\serializers.py", line 1052, in get_fields
    field_names = self.get_field_names(declared_fields, info)
                  ^^^^^^^^^^^^^^^^^^^^^^^^^^^^^^^^^^^^^^^^^^^
  File "C:\Users\ekad1\PycharmProjects\DjangoProjects\News Portal\venv\Lib\site-packages\rest_framework\serializers.py", line 1124, in get_field_names
    assert not (fields is None and exclude is None), (
                                   ^^^^^^^^^^^^^^^
AssertionError: ("Creating a ModelSerializer without either the 'fields' attribute or the 'exclude' attribute has been deprecated since 3.3.0, and is now disallowed. Add an explicit fields = '__all__' to the NewsSerializer serializer.",)
2023-11-04 15:47:02 ERROR "GET /api/news/ HTTP/1.1" 500 156335 C:\Users\ekad1\PycharmProjects\DjangoProjects\News Portal\venv\Lib\site-packages\django\core\servers\basehttp.py None
2023-11-04 15:54:40 ERROR Internal Server Error: /api/news/ C:\Users\ekad1\PycharmProjects\DjangoProjects\News Portal\venv\Lib\site-packages\django\utils\log.py (<class 'django.core.exceptions.ImproperlyConfigured'>, ImproperlyConfigured('Field name `Author__author_user` is not valid for model `Post`.'), <traceback object at 0x0000025A0F3DB900>)
Traceback (most recent call last):
  File "C:\Users\ekad1\PycharmProjects\DjangoProjects\News Portal\venv\Lib\site-packages\django\core\handlers\exception.py", line 55, in inner
    response = get_response(request)
               ^^^^^^^^^^^^^^^^^^^^^
  File "C:\Users\ekad1\PycharmProjects\DjangoProjects\News Portal\venv\Lib\site-packages\django\core\handlers\base.py", line 197, in _get_response
    response = wrapped_callback(request, *callback_args, **callback_kwargs)
               ^^^^^^^^^^^^^^^^^^^^^^^^^^^^^^^^^^^^^^^^^^^^^^^^^^^^^^^^^^^^
  File "C:\Users\ekad1\PycharmProjects\DjangoProjects\News Portal\venv\Lib\site-packages\django\views\decorators\csrf.py", line 56, in wrapper_view
    return view_func(*args, **kwargs)
           ^^^^^^^^^^^^^^^^^^^^^^^^^^
  File "C:\Users\ekad1\PycharmProjects\DjangoProjects\News Portal\venv\Lib\site-packages\rest_framework\viewsets.py", line 125, in view
    return self.dispatch(request, *args, **kwargs)
           ^^^^^^^^^^^^^^^^^^^^^^^^^^^^^^^^^^^^^^^
  File "C:\Users\ekad1\PycharmProjects\DjangoProjects\News Portal\venv\Lib\site-packages\rest_framework\views.py", line 509, in dispatch
    response = self.handle_exception(exc)
               ^^^^^^^^^^^^^^^^^^^^^^^^^^
  File "C:\Users\ekad1\PycharmProjects\DjangoProjects\News Portal\venv\Lib\site-packages\rest_framework\views.py", line 469, in handle_exception
    self.raise_uncaught_exception(exc)
  File "C:\Users\ekad1\PycharmProjects\DjangoProjects\News Portal\venv\Lib\site-packages\rest_framework\views.py", line 480, in raise_uncaught_exception
    raise exc
  File "C:\Users\ekad1\PycharmProjects\DjangoProjects\News Portal\venv\Lib\site-packages\rest_framework\views.py", line 506, in dispatch
    response = handler(request, *args, **kwargs)
               ^^^^^^^^^^^^^^^^^^^^^^^^^^^^^^^^^
  File "C:\Users\ekad1\PycharmProjects\DjangoProjects\News Portal\venv\Lib\site-packages\rest_framework\mixins.py", line 46, in list
    return Response(serializer.data)
                    ^^^^^^^^^^^^^^^
  File "C:\Users\ekad1\PycharmProjects\DjangoProjects\News Portal\venv\Lib\site-packages\rest_framework\serializers.py", line 768, in data
    ret = super().data
          ^^^^^^^^^^^^
  File "C:\Users\ekad1\PycharmProjects\DjangoProjects\News Portal\venv\Lib\site-packages\rest_framework\serializers.py", line 253, in data
    self._data = self.to_representation(self.instance)
                 ^^^^^^^^^^^^^^^^^^^^^^^^^^^^^^^^^^^^^
  File "C:\Users\ekad1\PycharmProjects\DjangoProjects\News Portal\venv\Lib\site-packages\rest_framework\serializers.py", line 686, in to_representation
    return [
           ^
  File "C:\Users\ekad1\PycharmProjects\DjangoProjects\News Portal\venv\Lib\site-packages\rest_framework\serializers.py", line 687, in <listcomp>
    self.child.to_representation(item) for item in iterable
    ^^^^^^^^^^^^^^^^^^^^^^^^^^^^^^^^^^
  File "C:\Users\ekad1\PycharmProjects\DjangoProjects\News Portal\venv\Lib\site-packages\rest_framework\serializers.py", line 507, in to_representation
    for field in fields:
  File "C:\Users\ekad1\PycharmProjects\DjangoProjects\News Portal\venv\Lib\site-packages\rest_framework\serializers.py", line 368, in _readable_fields
    for field in self.fields.values():
                 ^^^^^^^^^^^
  File "C:\Users\ekad1\PycharmProjects\DjangoProjects\News Portal\venv\Lib\site-packages\django\utils\functional.py", line 57, in __get__
    res = instance.__dict__[self.name] = self.func(instance)
                                         ^^^^^^^^^^^^^^^^^^^
  File "C:\Users\ekad1\PycharmProjects\DjangoProjects\News Portal\venv\Lib\site-packages\rest_framework\serializers.py", line 356, in fields
    for key, value in self.get_fields().items():
                      ^^^^^^^^^^^^^^^^^
  File "C:\Users\ekad1\PycharmProjects\DjangoProjects\News Portal\venv\Lib\site-packages\rest_framework\serializers.py", line 1076, in get_fields
    field_class, field_kwargs = self.build_field(
                                ^^^^^^^^^^^^^^^^^
  File "C:\Users\ekad1\PycharmProjects\DjangoProjects\News Portal\venv\Lib\site-packages\rest_framework\serializers.py", line 1222, in build_field
    return self.build_unknown_field(field_name, model_class)
           ^^^^^^^^^^^^^^^^^^^^^^^^^^^^^^^^^^^^^^^^^^^^^^^^^
  File "C:\Users\ekad1\PycharmProjects\DjangoProjects\News Portal\venv\Lib\site-packages\rest_framework\serializers.py", line 1340, in build_unknown_field
    raise ImproperlyConfigured(
django.core.exceptions.ImproperlyConfigured: Field name `Author__author_user` is not valid for model `Post`.
2023-11-04 15:54:40 ERROR "GET /api/news/ HTTP/1.1" 500 159315 C:\Users\ekad1\PycharmProjects\DjangoProjects\News Portal\venv\Lib\site-packages\django\core\servers\basehttp.py None
2023-11-04 15:55:25 ERROR Internal Server Error: /api/news/ C:\Users\ekad1\PycharmProjects\DjangoProjects\News Portal\venv\Lib\site-packages\django\utils\log.py (<class 'django.core.exceptions.ImproperlyConfigured'>, ImproperlyConfigured('Field name `post_author__author_user` is not valid for model `Post`.'), <traceback object at 0x00000161DE6DEE00>)
Traceback (most recent call last):
  File "C:\Users\ekad1\PycharmProjects\DjangoProjects\News Portal\venv\Lib\site-packages\django\core\handlers\exception.py", line 55, in inner
    response = get_response(request)
               ^^^^^^^^^^^^^^^^^^^^^
  File "C:\Users\ekad1\PycharmProjects\DjangoProjects\News Portal\venv\Lib\site-packages\django\core\handlers\base.py", line 197, in _get_response
    response = wrapped_callback(request, *callback_args, **callback_kwargs)
               ^^^^^^^^^^^^^^^^^^^^^^^^^^^^^^^^^^^^^^^^^^^^^^^^^^^^^^^^^^^^
  File "C:\Users\ekad1\PycharmProjects\DjangoProjects\News Portal\venv\Lib\site-packages\django\views\decorators\csrf.py", line 56, in wrapper_view
    return view_func(*args, **kwargs)
           ^^^^^^^^^^^^^^^^^^^^^^^^^^
  File "C:\Users\ekad1\PycharmProjects\DjangoProjects\News Portal\venv\Lib\site-packages\rest_framework\viewsets.py", line 125, in view
    return self.dispatch(request, *args, **kwargs)
           ^^^^^^^^^^^^^^^^^^^^^^^^^^^^^^^^^^^^^^^
  File "C:\Users\ekad1\PycharmProjects\DjangoProjects\News Portal\venv\Lib\site-packages\rest_framework\views.py", line 509, in dispatch
    response = self.handle_exception(exc)
               ^^^^^^^^^^^^^^^^^^^^^^^^^^
  File "C:\Users\ekad1\PycharmProjects\DjangoProjects\News Portal\venv\Lib\site-packages\rest_framework\views.py", line 469, in handle_exception
    self.raise_uncaught_exception(exc)
  File "C:\Users\ekad1\PycharmProjects\DjangoProjects\News Portal\venv\Lib\site-packages\rest_framework\views.py", line 480, in raise_uncaught_exception
    raise exc
  File "C:\Users\ekad1\PycharmProjects\DjangoProjects\News Portal\venv\Lib\site-packages\rest_framework\views.py", line 506, in dispatch
    response = handler(request, *args, **kwargs)
               ^^^^^^^^^^^^^^^^^^^^^^^^^^^^^^^^^
  File "C:\Users\ekad1\PycharmProjects\DjangoProjects\News Portal\venv\Lib\site-packages\rest_framework\mixins.py", line 46, in list
    return Response(serializer.data)
                    ^^^^^^^^^^^^^^^
  File "C:\Users\ekad1\PycharmProjects\DjangoProjects\News Portal\venv\Lib\site-packages\rest_framework\serializers.py", line 768, in data
    ret = super().data
          ^^^^^^^^^^^^
  File "C:\Users\ekad1\PycharmProjects\DjangoProjects\News Portal\venv\Lib\site-packages\rest_framework\serializers.py", line 253, in data
    self._data = self.to_representation(self.instance)
                 ^^^^^^^^^^^^^^^^^^^^^^^^^^^^^^^^^^^^^
  File "C:\Users\ekad1\PycharmProjects\DjangoProjects\News Portal\venv\Lib\site-packages\rest_framework\serializers.py", line 686, in to_representation
    return [
           ^
  File "C:\Users\ekad1\PycharmProjects\DjangoProjects\News Portal\venv\Lib\site-packages\rest_framework\serializers.py", line 687, in <listcomp>
    self.child.to_representation(item) for item in iterable
    ^^^^^^^^^^^^^^^^^^^^^^^^^^^^^^^^^^
  File "C:\Users\ekad1\PycharmProjects\DjangoProjects\News Portal\venv\Lib\site-packages\rest_framework\serializers.py", line 507, in to_representation
    for field in fields:
  File "C:\Users\ekad1\PycharmProjects\DjangoProjects\News Portal\venv\Lib\site-packages\rest_framework\serializers.py", line 368, in _readable_fields
    for field in self.fields.values():
                 ^^^^^^^^^^^
  File "C:\Users\ekad1\PycharmProjects\DjangoProjects\News Portal\venv\Lib\site-packages\django\utils\functional.py", line 57, in __get__
    res = instance.__dict__[self.name] = self.func(instance)
                                         ^^^^^^^^^^^^^^^^^^^
  File "C:\Users\ekad1\PycharmProjects\DjangoProjects\News Portal\venv\Lib\site-packages\rest_framework\serializers.py", line 356, in fields
    for key, value in self.get_fields().items():
                      ^^^^^^^^^^^^^^^^^
  File "C:\Users\ekad1\PycharmProjects\DjangoProjects\News Portal\venv\Lib\site-packages\rest_framework\serializers.py", line 1076, in get_fields
    field_class, field_kwargs = self.build_field(
                                ^^^^^^^^^^^^^^^^^
  File "C:\Users\ekad1\PycharmProjects\DjangoProjects\News Portal\venv\Lib\site-packages\rest_framework\serializers.py", line 1222, in build_field
    return self.build_unknown_field(field_name, model_class)
           ^^^^^^^^^^^^^^^^^^^^^^^^^^^^^^^^^^^^^^^^^^^^^^^^^
  File "C:\Users\ekad1\PycharmProjects\DjangoProjects\News Portal\venv\Lib\site-packages\rest_framework\serializers.py", line 1340, in build_unknown_field
    raise ImproperlyConfigured(
django.core.exceptions.ImproperlyConfigured: Field name `post_author__author_user` is not valid for model `Post`.
2023-11-04 15:55:25 ERROR "GET /api/news/ HTTP/1.1" 500 159430 C:\Users\ekad1\PycharmProjects\DjangoProjects\News Portal\venv\Lib\site-packages\django\core\servers\basehttp.py None
2023-11-04 16:02:24 ERROR Internal Server Error: /api/news/ C:\Users\ekad1\PycharmProjects\DjangoProjects\News Portal\venv\Lib\site-packages\django\utils\log.py (<class 'django.core.exceptions.ImproperlyConfigured'>, ImproperlyConfigured('Could not resolve URL for hyperlinked relationship using view name "author-detail". You may have failed to include the related model in your API, or incorrectly configured the `lookup_field` attribute on this field.'), <traceback object at 0x0000020772636E00>)
Traceback (most recent call last):
  File "C:\Users\ekad1\PycharmProjects\DjangoProjects\News Portal\venv\Lib\site-packages\rest_framework\relations.py", line 401, in to_representation
    url = self.get_url(value, self.view_name, request, format)
          ^^^^^^^^^^^^^^^^^^^^^^^^^^^^^^^^^^^^^^^^^^^^^^^^^^^^
  File "C:\Users\ekad1\PycharmProjects\DjangoProjects\News Portal\venv\Lib\site-packages\rest_framework\relations.py", line 339, in get_url
    return self.reverse(view_name, kwargs=kwargs, request=request, format=format)
           ^^^^^^^^^^^^^^^^^^^^^^^^^^^^^^^^^^^^^^^^^^^^^^^^^^^^^^^^^^^^^^^^^^^^^^
  File "C:\Users\ekad1\PycharmProjects\DjangoProjects\News Portal\venv\Lib\site-packages\rest_framework\reverse.py", line 47, in reverse
    url = _reverse(viewname, args, kwargs, request, format, **extra)
          ^^^^^^^^^^^^^^^^^^^^^^^^^^^^^^^^^^^^^^^^^^^^^^^^^^^^^^^^^^
  File "C:\Users\ekad1\PycharmProjects\DjangoProjects\News Portal\venv\Lib\site-packages\rest_framework\reverse.py", line 60, in _reverse
    url = django_reverse(viewname, args=args, kwargs=kwargs, **extra)
          ^^^^^^^^^^^^^^^^^^^^^^^^^^^^^^^^^^^^^^^^^^^^^^^^^^^^^^^^^^^
  File "C:\Users\ekad1\PycharmProjects\DjangoProjects\News Portal\venv\Lib\site-packages\django\urls\base.py", line 88, in reverse
    return resolver._reverse_with_prefix(view, prefix, *args, **kwargs)
           ^^^^^^^^^^^^^^^^^^^^^^^^^^^^^^^^^^^^^^^^^^^^^^^^^^^^^^^^^^^^
  File "C:\Users\ekad1\PycharmProjects\DjangoProjects\News Portal\venv\Lib\site-packages\django\urls\resolvers.py", line 828, in _reverse_with_prefix
    raise NoReverseMatch(msg)
django.urls.exceptions.NoReverseMatch: Reverse for 'author-detail' not found. 'author-detail' is not a valid view function or pattern name.

During handling of the above exception, another exception occurred:

Traceback (most recent call last):
  File "C:\Users\ekad1\PycharmProjects\DjangoProjects\News Portal\venv\Lib\site-packages\django\core\handlers\exception.py", line 55, in inner
    response = get_response(request)
               ^^^^^^^^^^^^^^^^^^^^^
  File "C:\Users\ekad1\PycharmProjects\DjangoProjects\News Portal\venv\Lib\site-packages\django\core\handlers\base.py", line 197, in _get_response
    response = wrapped_callback(request, *callback_args, **callback_kwargs)
               ^^^^^^^^^^^^^^^^^^^^^^^^^^^^^^^^^^^^^^^^^^^^^^^^^^^^^^^^^^^^
  File "C:\Users\ekad1\PycharmProjects\DjangoProjects\News Portal\venv\Lib\site-packages\django\views\decorators\csrf.py", line 56, in wrapper_view
    return view_func(*args, **kwargs)
           ^^^^^^^^^^^^^^^^^^^^^^^^^^
  File "C:\Users\ekad1\PycharmProjects\DjangoProjects\News Portal\venv\Lib\site-packages\rest_framework\viewsets.py", line 125, in view
    return self.dispatch(request, *args, **kwargs)
           ^^^^^^^^^^^^^^^^^^^^^^^^^^^^^^^^^^^^^^^
  File "C:\Users\ekad1\PycharmProjects\DjangoProjects\News Portal\venv\Lib\site-packages\rest_framework\views.py", line 509, in dispatch
    response = self.handle_exception(exc)
               ^^^^^^^^^^^^^^^^^^^^^^^^^^
  File "C:\Users\ekad1\PycharmProjects\DjangoProjects\News Portal\venv\Lib\site-packages\rest_framework\views.py", line 469, in handle_exception
    self.raise_uncaught_exception(exc)
  File "C:\Users\ekad1\PycharmProjects\DjangoProjects\News Portal\venv\Lib\site-packages\rest_framework\views.py", line 480, in raise_uncaught_exception
    raise exc
  File "C:\Users\ekad1\PycharmProjects\DjangoProjects\News Portal\venv\Lib\site-packages\rest_framework\views.py", line 506, in dispatch
    response = handler(request, *args, **kwargs)
               ^^^^^^^^^^^^^^^^^^^^^^^^^^^^^^^^^
  File "C:\Users\ekad1\PycharmProjects\DjangoProjects\News Portal\venv\Lib\site-packages\rest_framework\mixins.py", line 46, in list
    return Response(serializer.data)
                    ^^^^^^^^^^^^^^^
  File "C:\Users\ekad1\PycharmProjects\DjangoProjects\News Portal\venv\Lib\site-packages\rest_framework\serializers.py", line 768, in data
    ret = super().data
          ^^^^^^^^^^^^
  File "C:\Users\ekad1\PycharmProjects\DjangoProjects\News Portal\venv\Lib\site-packages\rest_framework\serializers.py", line 253, in data
    self._data = self.to_representation(self.instance)
                 ^^^^^^^^^^^^^^^^^^^^^^^^^^^^^^^^^^^^^
  File "C:\Users\ekad1\PycharmProjects\DjangoProjects\News Portal\venv\Lib\site-packages\rest_framework\serializers.py", line 686, in to_representation
    return [
           ^
  File "C:\Users\ekad1\PycharmProjects\DjangoProjects\News Portal\venv\Lib\site-packages\rest_framework\serializers.py", line 687, in <listcomp>
    self.child.to_representation(item) for item in iterable
    ^^^^^^^^^^^^^^^^^^^^^^^^^^^^^^^^^^
  File "C:\Users\ekad1\PycharmProjects\DjangoProjects\News Portal\venv\Lib\site-packages\rest_framework\serializers.py", line 522, in to_representation
    ret[field.field_name] = field.to_representation(attribute)
                            ^^^^^^^^^^^^^^^^^^^^^^^^^^^^^^^^^^
  File "C:\Users\ekad1\PycharmProjects\DjangoProjects\News Portal\venv\Lib\site-packages\rest_framework\relations.py", line 416, in to_representation
    raise ImproperlyConfigured(msg % self.view_name)
django.core.exceptions.ImproperlyConfigured: Could not resolve URL for hyperlinked relationship using view name "author-detail". You may have failed to include the related model in your API, or incorrectly configured the `lookup_field` attribute on this field.
2023-11-04 16:02:24 ERROR "GET /api/news/ HTTP/1.1" 500 169674 C:\Users\ekad1\PycharmProjects\DjangoProjects\News Portal\venv\Lib\site-packages\django\core\servers\basehttp.py None
2023-11-04 16:07:33 ERROR Internal Server Error: /api/news/ C:\Users\ekad1\PycharmProjects\DjangoProjects\News Portal\venv\Lib\site-packages\django\utils\log.py (<class 'django.core.exceptions.ImproperlyConfigured'>, ImproperlyConfigured('Field name `Author__post_author` is not valid for model `Post`.'), <traceback object at 0x000002AB296EA040>)
Traceback (most recent call last):
  File "C:\Users\ekad1\PycharmProjects\DjangoProjects\News Portal\venv\Lib\site-packages\django\core\handlers\exception.py", line 55, in inner
    response = get_response(request)
               ^^^^^^^^^^^^^^^^^^^^^
  File "C:\Users\ekad1\PycharmProjects\DjangoProjects\News Portal\venv\Lib\site-packages\django\core\handlers\base.py", line 197, in _get_response
    response = wrapped_callback(request, *callback_args, **callback_kwargs)
               ^^^^^^^^^^^^^^^^^^^^^^^^^^^^^^^^^^^^^^^^^^^^^^^^^^^^^^^^^^^^
  File "C:\Users\ekad1\PycharmProjects\DjangoProjects\News Portal\venv\Lib\site-packages\django\views\decorators\csrf.py", line 56, in wrapper_view
    return view_func(*args, **kwargs)
           ^^^^^^^^^^^^^^^^^^^^^^^^^^
  File "C:\Users\ekad1\PycharmProjects\DjangoProjects\News Portal\venv\Lib\site-packages\rest_framework\viewsets.py", line 125, in view
    return self.dispatch(request, *args, **kwargs)
           ^^^^^^^^^^^^^^^^^^^^^^^^^^^^^^^^^^^^^^^
  File "C:\Users\ekad1\PycharmProjects\DjangoProjects\News Portal\venv\Lib\site-packages\rest_framework\views.py", line 509, in dispatch
    response = self.handle_exception(exc)
               ^^^^^^^^^^^^^^^^^^^^^^^^^^
  File "C:\Users\ekad1\PycharmProjects\DjangoProjects\News Portal\venv\Lib\site-packages\rest_framework\views.py", line 469, in handle_exception
    self.raise_uncaught_exception(exc)
  File "C:\Users\ekad1\PycharmProjects\DjangoProjects\News Portal\venv\Lib\site-packages\rest_framework\views.py", line 480, in raise_uncaught_exception
    raise exc
  File "C:\Users\ekad1\PycharmProjects\DjangoProjects\News Portal\venv\Lib\site-packages\rest_framework\views.py", line 506, in dispatch
    response = handler(request, *args, **kwargs)
               ^^^^^^^^^^^^^^^^^^^^^^^^^^^^^^^^^
  File "C:\Users\ekad1\PycharmProjects\DjangoProjects\News Portal\venv\Lib\site-packages\rest_framework\mixins.py", line 46, in list
    return Response(serializer.data)
                    ^^^^^^^^^^^^^^^
  File "C:\Users\ekad1\PycharmProjects\DjangoProjects\News Portal\venv\Lib\site-packages\rest_framework\serializers.py", line 768, in data
    ret = super().data
          ^^^^^^^^^^^^
  File "C:\Users\ekad1\PycharmProjects\DjangoProjects\News Portal\venv\Lib\site-packages\rest_framework\serializers.py", line 253, in data
    self._data = self.to_representation(self.instance)
                 ^^^^^^^^^^^^^^^^^^^^^^^^^^^^^^^^^^^^^
  File "C:\Users\ekad1\PycharmProjects\DjangoProjects\News Portal\venv\Lib\site-packages\rest_framework\serializers.py", line 686, in to_representation
    return [
           ^
  File "C:\Users\ekad1\PycharmProjects\DjangoProjects\News Portal\venv\Lib\site-packages\rest_framework\serializers.py", line 687, in <listcomp>
    self.child.to_representation(item) for item in iterable
    ^^^^^^^^^^^^^^^^^^^^^^^^^^^^^^^^^^
  File "C:\Users\ekad1\PycharmProjects\DjangoProjects\News Portal\venv\Lib\site-packages\rest_framework\serializers.py", line 507, in to_representation
    for field in fields:
  File "C:\Users\ekad1\PycharmProjects\DjangoProjects\News Portal\venv\Lib\site-packages\rest_framework\serializers.py", line 368, in _readable_fields
    for field in self.fields.values():
                 ^^^^^^^^^^^
  File "C:\Users\ekad1\PycharmProjects\DjangoProjects\News Portal\venv\Lib\site-packages\django\utils\functional.py", line 57, in __get__
    res = instance.__dict__[self.name] = self.func(instance)
                                         ^^^^^^^^^^^^^^^^^^^
  File "C:\Users\ekad1\PycharmProjects\DjangoProjects\News Portal\venv\Lib\site-packages\rest_framework\serializers.py", line 356, in fields
    for key, value in self.get_fields().items():
                      ^^^^^^^^^^^^^^^^^
  File "C:\Users\ekad1\PycharmProjects\DjangoProjects\News Portal\venv\Lib\site-packages\rest_framework\serializers.py", line 1076, in get_fields
    field_class, field_kwargs = self.build_field(
                                ^^^^^^^^^^^^^^^^^
  File "C:\Users\ekad1\PycharmProjects\DjangoProjects\News Portal\venv\Lib\site-packages\rest_framework\serializers.py", line 1222, in build_field
    return self.build_unknown_field(field_name, model_class)
           ^^^^^^^^^^^^^^^^^^^^^^^^^^^^^^^^^^^^^^^^^^^^^^^^^
  File "C:\Users\ekad1\PycharmProjects\DjangoProjects\News Portal\venv\Lib\site-packages\rest_framework\serializers.py", line 1340, in build_unknown_field
    raise ImproperlyConfigured(
django.core.exceptions.ImproperlyConfigured: Field name `Author__post_author` is not valid for model `Post`.
2023-11-04 16:07:33 ERROR "GET /api/news/ HTTP/1.1" 500 159315 C:\Users\ekad1\PycharmProjects\DjangoProjects\News Portal\venv\Lib\site-packages\django\core\servers\basehttp.py None
2023-11-04 16:07:57 ERROR Internal Server Error: /api/news/ C:\Users\ekad1\PycharmProjects\DjangoProjects\News Portal\venv\Lib\site-packages\django\utils\log.py (<class 'django.core.exceptions.ImproperlyConfigured'>, ImproperlyConfigured('Could not resolve URL for hyperlinked relationship using view name "author-detail". You may have failed to include the related model in your API, or incorrectly configured the `lookup_field` attribute on this field.'), <traceback object at 0x000002415DBF9740>)
Traceback (most recent call last):
  File "C:\Users\ekad1\PycharmProjects\DjangoProjects\News Portal\venv\Lib\site-packages\rest_framework\relations.py", line 401, in to_representation
    url = self.get_url(value, self.view_name, request, format)
          ^^^^^^^^^^^^^^^^^^^^^^^^^^^^^^^^^^^^^^^^^^^^^^^^^^^^
  File "C:\Users\ekad1\PycharmProjects\DjangoProjects\News Portal\venv\Lib\site-packages\rest_framework\relations.py", line 339, in get_url
    return self.reverse(view_name, kwargs=kwargs, request=request, format=format)
           ^^^^^^^^^^^^^^^^^^^^^^^^^^^^^^^^^^^^^^^^^^^^^^^^^^^^^^^^^^^^^^^^^^^^^^
  File "C:\Users\ekad1\PycharmProjects\DjangoProjects\News Portal\venv\Lib\site-packages\rest_framework\reverse.py", line 47, in reverse
    url = _reverse(viewname, args, kwargs, request, format, **extra)
          ^^^^^^^^^^^^^^^^^^^^^^^^^^^^^^^^^^^^^^^^^^^^^^^^^^^^^^^^^^
  File "C:\Users\ekad1\PycharmProjects\DjangoProjects\News Portal\venv\Lib\site-packages\rest_framework\reverse.py", line 60, in _reverse
    url = django_reverse(viewname, args=args, kwargs=kwargs, **extra)
          ^^^^^^^^^^^^^^^^^^^^^^^^^^^^^^^^^^^^^^^^^^^^^^^^^^^^^^^^^^^
  File "C:\Users\ekad1\PycharmProjects\DjangoProjects\News Portal\venv\Lib\site-packages\django\urls\base.py", line 88, in reverse
    return resolver._reverse_with_prefix(view, prefix, *args, **kwargs)
           ^^^^^^^^^^^^^^^^^^^^^^^^^^^^^^^^^^^^^^^^^^^^^^^^^^^^^^^^^^^^
  File "C:\Users\ekad1\PycharmProjects\DjangoProjects\News Portal\venv\Lib\site-packages\django\urls\resolvers.py", line 828, in _reverse_with_prefix
    raise NoReverseMatch(msg)
django.urls.exceptions.NoReverseMatch: Reverse for 'author-detail' not found. 'author-detail' is not a valid view function or pattern name.

During handling of the above exception, another exception occurred:

Traceback (most recent call last):
  File "C:\Users\ekad1\PycharmProjects\DjangoProjects\News Portal\venv\Lib\site-packages\django\core\handlers\exception.py", line 55, in inner
    response = get_response(request)
               ^^^^^^^^^^^^^^^^^^^^^
  File "C:\Users\ekad1\PycharmProjects\DjangoProjects\News Portal\venv\Lib\site-packages\django\core\handlers\base.py", line 197, in _get_response
    response = wrapped_callback(request, *callback_args, **callback_kwargs)
               ^^^^^^^^^^^^^^^^^^^^^^^^^^^^^^^^^^^^^^^^^^^^^^^^^^^^^^^^^^^^
  File "C:\Users\ekad1\PycharmProjects\DjangoProjects\News Portal\venv\Lib\site-packages\django\views\decorators\csrf.py", line 56, in wrapper_view
    return view_func(*args, **kwargs)
           ^^^^^^^^^^^^^^^^^^^^^^^^^^
  File "C:\Users\ekad1\PycharmProjects\DjangoProjects\News Portal\venv\Lib\site-packages\rest_framework\viewsets.py", line 125, in view
    return self.dispatch(request, *args, **kwargs)
           ^^^^^^^^^^^^^^^^^^^^^^^^^^^^^^^^^^^^^^^
  File "C:\Users\ekad1\PycharmProjects\DjangoProjects\News Portal\venv\Lib\site-packages\rest_framework\views.py", line 509, in dispatch
    response = self.handle_exception(exc)
               ^^^^^^^^^^^^^^^^^^^^^^^^^^
  File "C:\Users\ekad1\PycharmProjects\DjangoProjects\News Portal\venv\Lib\site-packages\rest_framework\views.py", line 469, in handle_exception
    self.raise_uncaught_exception(exc)
  File "C:\Users\ekad1\PycharmProjects\DjangoProjects\News Portal\venv\Lib\site-packages\rest_framework\views.py", line 480, in raise_uncaught_exception
    raise exc
  File "C:\Users\ekad1\PycharmProjects\DjangoProjects\News Portal\venv\Lib\site-packages\rest_framework\views.py", line 506, in dispatch
    response = handler(request, *args, **kwargs)
               ^^^^^^^^^^^^^^^^^^^^^^^^^^^^^^^^^
  File "C:\Users\ekad1\PycharmProjects\DjangoProjects\News Portal\venv\Lib\site-packages\rest_framework\mixins.py", line 46, in list
    return Response(serializer.data)
                    ^^^^^^^^^^^^^^^
  File "C:\Users\ekad1\PycharmProjects\DjangoProjects\News Portal\venv\Lib\site-packages\rest_framework\serializers.py", line 768, in data
    ret = super().data
          ^^^^^^^^^^^^
  File "C:\Users\ekad1\PycharmProjects\DjangoProjects\News Portal\venv\Lib\site-packages\rest_framework\serializers.py", line 253, in data
    self._data = self.to_representation(self.instance)
                 ^^^^^^^^^^^^^^^^^^^^^^^^^^^^^^^^^^^^^
  File "C:\Users\ekad1\PycharmProjects\DjangoProjects\News Portal\venv\Lib\site-packages\rest_framework\serializers.py", line 686, in to_representation
    return [
           ^
  File "C:\Users\ekad1\PycharmProjects\DjangoProjects\News Portal\venv\Lib\site-packages\rest_framework\serializers.py", line 687, in <listcomp>
    self.child.to_representation(item) for item in iterable
    ^^^^^^^^^^^^^^^^^^^^^^^^^^^^^^^^^^
  File "C:\Users\ekad1\PycharmProjects\DjangoProjects\News Portal\venv\Lib\site-packages\rest_framework\serializers.py", line 522, in to_representation
    ret[field.field_name] = field.to_representation(attribute)
                            ^^^^^^^^^^^^^^^^^^^^^^^^^^^^^^^^^^
  File "C:\Users\ekad1\PycharmProjects\DjangoProjects\News Portal\venv\Lib\site-packages\rest_framework\relations.py", line 416, in to_representation
    raise ImproperlyConfigured(msg % self.view_name)
django.core.exceptions.ImproperlyConfigured: Could not resolve URL for hyperlinked relationship using view name "author-detail". You may have failed to include the related model in your API, or incorrectly configured the `lookup_field` attribute on this field.
2023-11-04 16:07:57 ERROR "GET /api/news/ HTTP/1.1" 500 169674 C:\Users\ekad1\PycharmProjects\DjangoProjects\News Portal\venv\Lib\site-packages\django\core\servers\basehttp.py None
2023-11-04 16:15:26 ERROR Internal Server Error: /api/news/ C:\Users\ekad1\PycharmProjects\DjangoProjects\News Portal\venv\Lib\site-packages\django\utils\log.py (<class 'django.core.exceptions.ImproperlyConfigured'>, ImproperlyConfigured('Could not resolve URL for hyperlinked relationship using view name "author-detail". You may have failed to include the related model in your API, or incorrectly configured the `lookup_field` attribute on this field.'), <traceback object at 0x000002441A704D80>)
Traceback (most recent call last):
  File "C:\Users\ekad1\PycharmProjects\DjangoProjects\News Portal\venv\Lib\site-packages\rest_framework\relations.py", line 401, in to_representation
    url = self.get_url(value, self.view_name, request, format)
          ^^^^^^^^^^^^^^^^^^^^^^^^^^^^^^^^^^^^^^^^^^^^^^^^^^^^
  File "C:\Users\ekad1\PycharmProjects\DjangoProjects\News Portal\venv\Lib\site-packages\rest_framework\relations.py", line 339, in get_url
    return self.reverse(view_name, kwargs=kwargs, request=request, format=format)
           ^^^^^^^^^^^^^^^^^^^^^^^^^^^^^^^^^^^^^^^^^^^^^^^^^^^^^^^^^^^^^^^^^^^^^^
  File "C:\Users\ekad1\PycharmProjects\DjangoProjects\News Portal\venv\Lib\site-packages\rest_framework\reverse.py", line 47, in reverse
    url = _reverse(viewname, args, kwargs, request, format, **extra)
          ^^^^^^^^^^^^^^^^^^^^^^^^^^^^^^^^^^^^^^^^^^^^^^^^^^^^^^^^^^
  File "C:\Users\ekad1\PycharmProjects\DjangoProjects\News Portal\venv\Lib\site-packages\rest_framework\reverse.py", line 60, in _reverse
    url = django_reverse(viewname, args=args, kwargs=kwargs, **extra)
          ^^^^^^^^^^^^^^^^^^^^^^^^^^^^^^^^^^^^^^^^^^^^^^^^^^^^^^^^^^^
  File "C:\Users\ekad1\PycharmProjects\DjangoProjects\News Portal\venv\Lib\site-packages\django\urls\base.py", line 88, in reverse
    return resolver._reverse_with_prefix(view, prefix, *args, **kwargs)
           ^^^^^^^^^^^^^^^^^^^^^^^^^^^^^^^^^^^^^^^^^^^^^^^^^^^^^^^^^^^^
  File "C:\Users\ekad1\PycharmProjects\DjangoProjects\News Portal\venv\Lib\site-packages\django\urls\resolvers.py", line 828, in _reverse_with_prefix
    raise NoReverseMatch(msg)
django.urls.exceptions.NoReverseMatch: Reverse for 'author-detail' not found. 'author-detail' is not a valid view function or pattern name.

During handling of the above exception, another exception occurred:

Traceback (most recent call last):
  File "C:\Users\ekad1\PycharmProjects\DjangoProjects\News Portal\venv\Lib\site-packages\django\core\handlers\exception.py", line 55, in inner
    response = get_response(request)
               ^^^^^^^^^^^^^^^^^^^^^
  File "C:\Users\ekad1\PycharmProjects\DjangoProjects\News Portal\venv\Lib\site-packages\django\core\handlers\base.py", line 197, in _get_response
    response = wrapped_callback(request, *callback_args, **callback_kwargs)
               ^^^^^^^^^^^^^^^^^^^^^^^^^^^^^^^^^^^^^^^^^^^^^^^^^^^^^^^^^^^^
  File "C:\Users\ekad1\PycharmProjects\DjangoProjects\News Portal\venv\Lib\site-packages\django\views\decorators\csrf.py", line 56, in wrapper_view
    return view_func(*args, **kwargs)
           ^^^^^^^^^^^^^^^^^^^^^^^^^^
  File "C:\Users\ekad1\PycharmProjects\DjangoProjects\News Portal\venv\Lib\site-packages\rest_framework\viewsets.py", line 125, in view
    return self.dispatch(request, *args, **kwargs)
           ^^^^^^^^^^^^^^^^^^^^^^^^^^^^^^^^^^^^^^^
  File "C:\Users\ekad1\PycharmProjects\DjangoProjects\News Portal\venv\Lib\site-packages\rest_framework\views.py", line 509, in dispatch
    response = self.handle_exception(exc)
               ^^^^^^^^^^^^^^^^^^^^^^^^^^
  File "C:\Users\ekad1\PycharmProjects\DjangoProjects\News Portal\venv\Lib\site-packages\rest_framework\views.py", line 469, in handle_exception
    self.raise_uncaught_exception(exc)
  File "C:\Users\ekad1\PycharmProjects\DjangoProjects\News Portal\venv\Lib\site-packages\rest_framework\views.py", line 480, in raise_uncaught_exception
    raise exc
  File "C:\Users\ekad1\PycharmProjects\DjangoProjects\News Portal\venv\Lib\site-packages\rest_framework\views.py", line 506, in dispatch
    response = handler(request, *args, **kwargs)
               ^^^^^^^^^^^^^^^^^^^^^^^^^^^^^^^^^
  File "C:\Users\ekad1\PycharmProjects\DjangoProjects\News Portal\venv\Lib\site-packages\rest_framework\mixins.py", line 46, in list
    return Response(serializer.data)
                    ^^^^^^^^^^^^^^^
  File "C:\Users\ekad1\PycharmProjects\DjangoProjects\News Portal\venv\Lib\site-packages\rest_framework\serializers.py", line 768, in data
    ret = super().data
          ^^^^^^^^^^^^
  File "C:\Users\ekad1\PycharmProjects\DjangoProjects\News Portal\venv\Lib\site-packages\rest_framework\serializers.py", line 253, in data
    self._data = self.to_representation(self.instance)
                 ^^^^^^^^^^^^^^^^^^^^^^^^^^^^^^^^^^^^^
  File "C:\Users\ekad1\PycharmProjects\DjangoProjects\News Portal\venv\Lib\site-packages\rest_framework\serializers.py", line 686, in to_representation
    return [
           ^
  File "C:\Users\ekad1\PycharmProjects\DjangoProjects\News Portal\venv\Lib\site-packages\rest_framework\serializers.py", line 687, in <listcomp>
    self.child.to_representation(item) for item in iterable
    ^^^^^^^^^^^^^^^^^^^^^^^^^^^^^^^^^^
  File "C:\Users\ekad1\PycharmProjects\DjangoProjects\News Portal\venv\Lib\site-packages\rest_framework\serializers.py", line 522, in to_representation
    ret[field.field_name] = field.to_representation(attribute)
                            ^^^^^^^^^^^^^^^^^^^^^^^^^^^^^^^^^^
  File "C:\Users\ekad1\PycharmProjects\DjangoProjects\News Portal\venv\Lib\site-packages\rest_framework\relations.py", line 416, in to_representation
    raise ImproperlyConfigured(msg % self.view_name)
django.core.exceptions.ImproperlyConfigured: Could not resolve URL for hyperlinked relationship using view name "author-detail". You may have failed to include the related model in your API, or incorrectly configured the `lookup_field` attribute on this field.
2023-11-04 16:15:26 ERROR "GET /api/news/ HTTP/1.1" 500 169674 C:\Users\ekad1\PycharmProjects\DjangoProjects\News Portal\venv\Lib\site-packages\django\core\servers\basehttp.py None
2023-11-04 16:17:21 ERROR Internal Server Error: /api/author/1/ C:\Users\ekad1\PycharmProjects\DjangoProjects\News Portal\venv\Lib\site-packages\django\utils\log.py (<class 'django.core.exceptions.ImproperlyConfigured'>, ImproperlyConfigured('Could not resolve URL for hyperlinked relationship using view name "user-detail". You may have failed to include the related model in your API, or incorrectly configured the `lookup_field` attribute on this field.'), <traceback object at 0x00000148091DE080>)
Traceback (most recent call last):
  File "C:\Users\ekad1\PycharmProjects\DjangoProjects\News Portal\venv\Lib\site-packages\rest_framework\relations.py", line 401, in to_representation
    url = self.get_url(value, self.view_name, request, format)
          ^^^^^^^^^^^^^^^^^^^^^^^^^^^^^^^^^^^^^^^^^^^^^^^^^^^^
  File "C:\Users\ekad1\PycharmProjects\DjangoProjects\News Portal\venv\Lib\site-packages\rest_framework\relations.py", line 339, in get_url
    return self.reverse(view_name, kwargs=kwargs, request=request, format=format)
           ^^^^^^^^^^^^^^^^^^^^^^^^^^^^^^^^^^^^^^^^^^^^^^^^^^^^^^^^^^^^^^^^^^^^^^
  File "C:\Users\ekad1\PycharmProjects\DjangoProjects\News Portal\venv\Lib\site-packages\rest_framework\reverse.py", line 47, in reverse
    url = _reverse(viewname, args, kwargs, request, format, **extra)
          ^^^^^^^^^^^^^^^^^^^^^^^^^^^^^^^^^^^^^^^^^^^^^^^^^^^^^^^^^^
  File "C:\Users\ekad1\PycharmProjects\DjangoProjects\News Portal\venv\Lib\site-packages\rest_framework\reverse.py", line 60, in _reverse
    url = django_reverse(viewname, args=args, kwargs=kwargs, **extra)
          ^^^^^^^^^^^^^^^^^^^^^^^^^^^^^^^^^^^^^^^^^^^^^^^^^^^^^^^^^^^
  File "C:\Users\ekad1\PycharmProjects\DjangoProjects\News Portal\venv\Lib\site-packages\django\urls\base.py", line 88, in reverse
    return resolver._reverse_with_prefix(view, prefix, *args, **kwargs)
           ^^^^^^^^^^^^^^^^^^^^^^^^^^^^^^^^^^^^^^^^^^^^^^^^^^^^^^^^^^^^
  File "C:\Users\ekad1\PycharmProjects\DjangoProjects\News Portal\venv\Lib\site-packages\django\urls\resolvers.py", line 828, in _reverse_with_prefix
    raise NoReverseMatch(msg)
django.urls.exceptions.NoReverseMatch: Reverse for 'user-detail' not found. 'user-detail' is not a valid view function or pattern name.

During handling of the above exception, another exception occurred:

Traceback (most recent call last):
  File "C:\Users\ekad1\PycharmProjects\DjangoProjects\News Portal\venv\Lib\site-packages\django\core\handlers\exception.py", line 55, in inner
    response = get_response(request)
               ^^^^^^^^^^^^^^^^^^^^^
  File "C:\Users\ekad1\PycharmProjects\DjangoProjects\News Portal\venv\Lib\site-packages\django\core\handlers\base.py", line 197, in _get_response
    response = wrapped_callback(request, *callback_args, **callback_kwargs)
               ^^^^^^^^^^^^^^^^^^^^^^^^^^^^^^^^^^^^^^^^^^^^^^^^^^^^^^^^^^^^
  File "C:\Users\ekad1\PycharmProjects\DjangoProjects\News Portal\venv\Lib\site-packages\django\views\decorators\csrf.py", line 56, in wrapper_view
    return view_func(*args, **kwargs)
           ^^^^^^^^^^^^^^^^^^^^^^^^^^
  File "C:\Users\ekad1\PycharmProjects\DjangoProjects\News Portal\venv\Lib\site-packages\rest_framework\viewsets.py", line 125, in view
    return self.dispatch(request, *args, **kwargs)
           ^^^^^^^^^^^^^^^^^^^^^^^^^^^^^^^^^^^^^^^
  File "C:\Users\ekad1\PycharmProjects\DjangoProjects\News Portal\venv\Lib\site-packages\rest_framework\views.py", line 509, in dispatch
    response = self.handle_exception(exc)
               ^^^^^^^^^^^^^^^^^^^^^^^^^^
  File "C:\Users\ekad1\PycharmProjects\DjangoProjects\News Portal\venv\Lib\site-packages\rest_framework\views.py", line 469, in handle_exception
    self.raise_uncaught_exception(exc)
  File "C:\Users\ekad1\PycharmProjects\DjangoProjects\News Portal\venv\Lib\site-packages\rest_framework\views.py", line 480, in raise_uncaught_exception
    raise exc
  File "C:\Users\ekad1\PycharmProjects\DjangoProjects\News Portal\venv\Lib\site-packages\rest_framework\views.py", line 506, in dispatch
    response = handler(request, *args, **kwargs)
               ^^^^^^^^^^^^^^^^^^^^^^^^^^^^^^^^^
  File "C:\Users\ekad1\PycharmProjects\DjangoProjects\News Portal\venv\Lib\site-packages\rest_framework\mixins.py", line 56, in retrieve
    return Response(serializer.data)
                    ^^^^^^^^^^^^^^^
  File "C:\Users\ekad1\PycharmProjects\DjangoProjects\News Portal\venv\Lib\site-packages\rest_framework\serializers.py", line 555, in data
    ret = super().data
          ^^^^^^^^^^^^
  File "C:\Users\ekad1\PycharmProjects\DjangoProjects\News Portal\venv\Lib\site-packages\rest_framework\serializers.py", line 253, in data
    self._data = self.to_representation(self.instance)
                 ^^^^^^^^^^^^^^^^^^^^^^^^^^^^^^^^^^^^^
  File "C:\Users\ekad1\PycharmProjects\DjangoProjects\News Portal\venv\Lib\site-packages\rest_framework\serializers.py", line 522, in to_representation
    ret[field.field_name] = field.to_representation(attribute)
                            ^^^^^^^^^^^^^^^^^^^^^^^^^^^^^^^^^^
  File "C:\Users\ekad1\PycharmProjects\DjangoProjects\News Portal\venv\Lib\site-packages\rest_framework\relations.py", line 416, in to_representation
    raise ImproperlyConfigured(msg % self.view_name)
django.core.exceptions.ImproperlyConfigured: Could not resolve URL for hyperlinked relationship using view name "user-detail". You may have failed to include the related model in your API, or incorrectly configured the `lookup_field` attribute on this field.
2023-11-04 16:17:21 ERROR "GET /api/author/1/ HTTP/1.1" 500 155138 C:\Users\ekad1\PycharmProjects\DjangoProjects\News Portal\venv\Lib\site-packages\django\core\servers\basehttp.py None
2023-11-04 16:21:42 ERROR Internal Server Error: /api/user/1/ C:\Users\ekad1\PycharmProjects\DjangoProjects\News Portal\venv\Lib\site-packages\django\utils\log.py (<class 'django.core.exceptions.ImproperlyConfigured'>, ImproperlyConfigured('Field name `name` is not valid for model `User`.'), <traceback object at 0x000002279E48B500>)
Traceback (most recent call last):
  File "C:\Users\ekad1\PycharmProjects\DjangoProjects\News Portal\venv\Lib\site-packages\django\core\handlers\exception.py", line 55, in inner
    response = get_response(request)
               ^^^^^^^^^^^^^^^^^^^^^
  File "C:\Users\ekad1\PycharmProjects\DjangoProjects\News Portal\venv\Lib\site-packages\django\core\handlers\base.py", line 197, in _get_response
    response = wrapped_callback(request, *callback_args, **callback_kwargs)
               ^^^^^^^^^^^^^^^^^^^^^^^^^^^^^^^^^^^^^^^^^^^^^^^^^^^^^^^^^^^^
  File "C:\Users\ekad1\PycharmProjects\DjangoProjects\News Portal\venv\Lib\site-packages\django\views\decorators\csrf.py", line 56, in wrapper_view
    return view_func(*args, **kwargs)
           ^^^^^^^^^^^^^^^^^^^^^^^^^^
  File "C:\Users\ekad1\PycharmProjects\DjangoProjects\News Portal\venv\Lib\site-packages\rest_framework\viewsets.py", line 125, in view
    return self.dispatch(request, *args, **kwargs)
           ^^^^^^^^^^^^^^^^^^^^^^^^^^^^^^^^^^^^^^^
  File "C:\Users\ekad1\PycharmProjects\DjangoProjects\News Portal\venv\Lib\site-packages\rest_framework\views.py", line 509, in dispatch
    response = self.handle_exception(exc)
               ^^^^^^^^^^^^^^^^^^^^^^^^^^
  File "C:\Users\ekad1\PycharmProjects\DjangoProjects\News Portal\venv\Lib\site-packages\rest_framework\views.py", line 469, in handle_exception
    self.raise_uncaught_exception(exc)
  File "C:\Users\ekad1\PycharmProjects\DjangoProjects\News Portal\venv\Lib\site-packages\rest_framework\views.py", line 480, in raise_uncaught_exception
    raise exc
  File "C:\Users\ekad1\PycharmProjects\DjangoProjects\News Portal\venv\Lib\site-packages\rest_framework\views.py", line 506, in dispatch
    response = handler(request, *args, **kwargs)
               ^^^^^^^^^^^^^^^^^^^^^^^^^^^^^^^^^
  File "C:\Users\ekad1\PycharmProjects\DjangoProjects\News Portal\venv\Lib\site-packages\rest_framework\mixins.py", line 56, in retrieve
    return Response(serializer.data)
                    ^^^^^^^^^^^^^^^
  File "C:\Users\ekad1\PycharmProjects\DjangoProjects\News Portal\venv\Lib\site-packages\rest_framework\serializers.py", line 555, in data
    ret = super().data
          ^^^^^^^^^^^^
  File "C:\Users\ekad1\PycharmProjects\DjangoProjects\News Portal\venv\Lib\site-packages\rest_framework\serializers.py", line 253, in data
    self._data = self.to_representation(self.instance)
                 ^^^^^^^^^^^^^^^^^^^^^^^^^^^^^^^^^^^^^
  File "C:\Users\ekad1\PycharmProjects\DjangoProjects\News Portal\venv\Lib\site-packages\rest_framework\serializers.py", line 507, in to_representation
    for field in fields:
  File "C:\Users\ekad1\PycharmProjects\DjangoProjects\News Portal\venv\Lib\site-packages\rest_framework\serializers.py", line 368, in _readable_fields
    for field in self.fields.values():
                 ^^^^^^^^^^^
  File "C:\Users\ekad1\PycharmProjects\DjangoProjects\News Portal\venv\Lib\site-packages\django\utils\functional.py", line 57, in __get__
    res = instance.__dict__[self.name] = self.func(instance)
                                         ^^^^^^^^^^^^^^^^^^^
  File "C:\Users\ekad1\PycharmProjects\DjangoProjects\News Portal\venv\Lib\site-packages\rest_framework\serializers.py", line 356, in fields
    for key, value in self.get_fields().items():
                      ^^^^^^^^^^^^^^^^^
  File "C:\Users\ekad1\PycharmProjects\DjangoProjects\News Portal\venv\Lib\site-packages\rest_framework\serializers.py", line 1076, in get_fields
    field_class, field_kwargs = self.build_field(
                                ^^^^^^^^^^^^^^^^^
  File "C:\Users\ekad1\PycharmProjects\DjangoProjects\News Portal\venv\Lib\site-packages\rest_framework\serializers.py", line 1222, in build_field
    return self.build_unknown_field(field_name, model_class)
           ^^^^^^^^^^^^^^^^^^^^^^^^^^^^^^^^^^^^^^^^^^^^^^^^^
  File "C:\Users\ekad1\PycharmProjects\DjangoProjects\News Portal\venv\Lib\site-packages\rest_framework\serializers.py", line 1340, in build_unknown_field
    raise ImproperlyConfigured(
django.core.exceptions.ImproperlyConfigured: Field name `name` is not valid for model `User`.
2023-11-04 16:21:42 ERROR "GET /api/user/1/ HTTP/1.1" 500 152874 C:\Users\ekad1\PycharmProjects\DjangoProjects\News Portal\venv\Lib\site-packages\django\core\servers\basehttp.py None
